Workbook

Sheet Квартал 1
A1: Продан | C1: Бронь | E1: В продаже | H1: цветочные обозначения какие планировки
H3: обозначение 1 и 2х этажных домов
A8: Айвазовского | I8: Прогулочная аллея | K8: Айвазовского | V8: Айвазовского | AF8: Айвазовского
A11: 1642 | B11: 1650 | C11: 1651 | D11: 1652 | E11: 1653 | F11: 1654 | G11: 1655 | H11: 1656 | K11: 1538 | L11: 1546 | M11: 1547 | N11: 1548 | O11: 1549 | P11: 1550 | Q11: 1551 | R11: 1552 | V11: 1590 | W11: 1600 | X11: 1601 | Y11: 1602 | Z11: 1603 | AA11: 1604 | AB11: 1605 | AC11: 1606 | AD11: 1607 | AF11: 1572 | AG11: 1582 | AH11: 1583 | AI11: 1584 | AJ11: 1585 | AK11: 1586 | AL11: 1587 | AM11: 1588 | AN11: 1589
A13: 1649 | B13: 1648 | C13: 1647 | D13: 1646 | E13: 1645 | F13: 1644 | G13: 1643 | H13: 1657 | K13: 1545 | L13: 1544 | M13: 1543 | N13: 1542 | O13: 1541 | P13: 1540 | Q13: 1539 | R13: 1553 | V13: 1599 | W13: 1598 | X13: 1597 | Y13: 1596 | Z13: 1595 | AA13: 1594 | AB13: 1593 | AC13: 1592 | AD13: 1591 | AF13: 1581 | AG13: 1580 | AH13: 1579 | AI13: 1578 | AJ13: 1577 | AK13: 1576 | AL13: 1575 | AM13: 1574 | AN13: 1573
A15: Луначарского | K15: Луначарского | V15: Луначарского | AF15: Луначарского
A18: 1673 | B18: 1679 | C18: 1680 | D18: 1681 | E18: 1682 | F18: 1683 | G18: 1684 | K18: 1658 | M18: 1664 | N18: 1665 | O18: 1666 | P18: 1667 | Q18: 1668 | R18: 1669 | V18: 1687 | W18: 1695 | X18: 1696 | Y18: 1697 | Z18: 1698 | AA18: 1699 | AB18: 1700 | AC18: 1701 | AF18: 1703 | AG18: 1710 | AH18: 1711 | AI18: 1712 | AJ18: 1713 | AK18: 1714 | AL18: 1715
AF19: 1709
A20: 1678 | B20: 1677 | C20: 1676 | D20: 1675 | E20: 1674 | F20: 1686 | G20: 1685 | K20: 1663 | M20: 1662 | N20: 1661 | O20: 1660 | P20: 1659 | Q20: 1671 | R20: 1670 | V20: 1694 | W20: 1693 | X20: 1692 | Y20: 1691 | Z20: 1690 | AA20: 1689 | AB20: 1688 | AC20: 1702 | AF20: 1708 | AG20: 1706 | AH20: 1707 | AI20: 1705 | AJ20: 1704 | AK20: 1717 | AL20: 1716
A22: Дивноморская | K22: Дивноморская | V22: Дивноморская | AF22: Дивноморская
B32: калькулятор

Sheet Ген. план
A1: Château Del Mare
D10: въезд в поселок | K10: Участок | L10: Дом
K11: 1538
K12: 1539
K13: 1540 | AR13: Резерв
K14: 1541
K15: 1542
K16: 1543
K17: 1544
K18: 1545
A19: Лиман | K19: 1546
K20: 1547
K21: 1548
A22: Вид на виноградники, лиман | K22: 1549
K23: 1550
K24: 1551
A25: Вид на море и лиманы | K25: 1552
K26: 1553
K27: 1572
A28: Вид бугазскую косу | K28: 1573
K29: 1574
K30: 1575
K31: 1576
K32: 1577
K33: 1578
K34: 1579
K35: 1580
K36: 1581
K37: 1582
K38: 1583
K39: 1584
K40: 1585
... K43: 1588
D44: инфраструктура поселка ? | K44: 1589
K45: 1590
K46: 1591
K47: 1592
K48: 1593
K49: 1594
K50: 1595
...

Sheet Каталог
A1: Проект | B1: Этажей | C1: Дом м² | D1: Черновая ₽ | E1: ПЧО ₽ | F1: Под ключ ₽ | G1: ₽/м² дома
A2: Костеро | B2: 1 | C2: 32 | D2: 5379000 | E2: 5709000 | F2: 6094000 | G2: =IF(AND(F2>0,C2>0),ROUND(F2/C2,0),"")
A3: Линия 40 | B3: 1 | C3: 40 | D3: 7000000 | E3: 7600000 | F3: 8500000 | G3: =IF(AND(F3>0,C3>0),ROUND(F3/C3,0),"")
A4: Линия 72 | B4: 1 | C4: 72 | D4: 9190000 | E4: 9990000 | F4: 11260000 | G4: =IF(AND(F4>0,C4>0),ROUND(F4/C4,0),"")
A5: Логос | B5: 1 | C5: 64 | D5: 8300000 | E5: 9090000 | F5: 10990000 | G5: =IF(AND(F5>0,C5>0),ROUND(F5/C5,0),"")
A6: Логос мини | B6: 1 | C6: 40 | D6: 7000000 | E6: 7600000 | F6: 8500000 | G6: =IF(AND(F6>0,C6>0),ROUND(F6/C6,0),"")
A7: Палаццо | B7: 2 | C7: 80 | D7: 9490000 | E7: 10190000 | F7: 11990000 | G7: =IF(AND(F7>0,C7>0),ROUND(F7/C7,0),"")
A8: Эдем | B8: 2 | C8: 60 | D8: 8300000 | E8: 9090000 | F8: 10990000 | G8: =IF(AND(F8>0,C8>0),ROUND(F8/C8,0),"")
A9: Арбор | B9: 1 | C9: 32 | D9: 5379000 | E9: 5819000 | F9: 6369000 | G9: =IF(AND(F9>0,C9>0),ROUND(F9/C9,0),"")
A10: Баня | B10: 1 | C10: 24 | D10: 2500000 | E10: 2800000 | F10: 3200000 | G10: =IF(AND(F10>0,C10>0),ROUND(F10/C10,0),"")
A11: Вилла Маре | B11: 2 | C11: 136 | D11: 10390000 | E11: 11100000 | F11: 12850000 | G11: =IF(AND(F11>0,C11>0),ROUND(F11/C11,0),"")

Sheet Прайс
A1: Параметр | B1: Значение
A2: ₽/м² земли (база из каталога) | B2: =ROUND(MIN('Каталог'!F2:F11)/B4,0)
A3: Надбавка угловой (₽/м² к дому) | B3: 1000
A4: Участок в базе дома (м²) | B4: 500
A5: Источник ставки | B5: MIN(дом под ключ) / 500 м²
A6: Вид | B6: ₽/м² (если пусто — база)
A7: Виноградники / лиман / вулканы
A8: Вид на море
A9: Панорама

Sheet Данные участки
A1: № участка | B1: Улица | C1: Площадь м² | D1: Вид | E1: Статус | F1: Угловой | G1: Зона домов | H1: Допустимые дома | I1: Проект (каталог) | J1: ₽/м² земли | K1: Цена земли | L1: Надбавка к дому | M1: Дом под ключ | N1: ИТОГО
A2: 1454 | B2: Цветочная | C2: 542 | E2: Продано | F2: Да | G2: — | H2: — | J2: {=IF(I2<>"",ROUND(INDEX('Каталог'!$F:$F,MATCH(I2,'Каталог'!$A:$A,0))/'Прайс'!$B$4,0),IFERROR(VLOOKUP(D2,'Прайс'!$A$7:$B$9,2,FALSE),'Прайс'!$B$2))} | K2: =IF(AND(C2>0,J2>0,E2<>"Продано"),ROUND(C2*J2,0),"") | L2: =IF(AND(F2="Да",C2>0,E2<>"Продано"),ROUND(C2*'Прайс'!$B$3,0),0) | M2: {=IF(I2<>"",INDEX('Каталог'!$F:$F,MATCH(I2,'Каталог'!$A:$A,0)),"")} | N2: =IF(AND(E2<>"Продано",OR(K2>0,M2>0)),IFERROR(K2,0)+IFERROR(M2,0)+IFERROR(L2,0),"")
A3: 1457 | B3: Цветочная | E3: Продано | F3: Нет | G3: — | H3: — | J3: {=IF(I3<>"",ROUND(INDEX('Каталог'!$F:$F,MATCH(I3,'Каталог'!$A:$A,0))/'Прайс'!$B$4,0),IFERROR(VLOOKUP(D3,'Прайс'!$A$7:$B$9,2,FALSE),'Прайс'!$B$2))} | K3: =IF(AND(C3>0,J3>0,E3<>"Продано"),ROUND(C3*J3,0),"") | L3: =IF(AND(F3="Да",C3>0,E3<>"Продано"),ROUND(C3*'Прайс'!$B$3,0),0) | M3: {=IF(I3<>"",INDEX('Каталог'!$F:$F,MATCH(I3,'Каталог'!$A:$A,0)),"")} | N3: =IF(AND(E3<>"Продано",OR(K3>0,M3>0)),IFERROR(K3,0)+IFERROR(M3,0)+IFERROR(L3,0),"")
A4: 1465 | B4: Цветочная | E4: Продано | F4: Нет | G4: — | H4: — | J4: {=IF(I4<>"",ROUND(INDEX('Каталог'!$F:$F,MATCH(I4,'Каталог'!$A:$A,0))/'Прайс'!$B$4,0),IFERROR(VLOOKUP(D4,'Прайс'!$A$7:$B$9,2,FALSE),'Прайс'!$B$2))} | K4: =IF(AND(C4>0,J4>0,E4<>"Продано"),ROUND(C4*J4,0),"") | L4: =IF(AND(F4="Да",C4>0,E4<>"Продано"),ROUND(C4*'Прайс'!$B$3,0),0) | M4: {=IF(I4<>"",INDEX('Каталог'!$F:$F,MATCH(I4,'Каталог'!$A:$A,0)),"")} | N4: =IF(AND(E4<>"Продано",OR(K4>0,M4>0)),IFERROR(K4,0)+IFERROR(M4,0)+IFERROR(L4,0),"")
A5: 1466 | B5: Цветочная | E5: Продано | F5: Нет | G5: — | H5: — | J5: {=IF(I5<>"",ROUND(INDEX('Каталог'!$F:$F,MATCH(I5,'Каталог'!$A:$A,0))/'Прайс'!$B$4,0),IFERROR(VLOOKUP(D5,'Прайс'!$A$7:$B$9,2,FALSE),'Прайс'!$B$2))} | K5: =IF(AND(C5>0,J5>0,E5<>"Продано"),ROUND(C5*J5,0),"") | L5: =IF(AND(F5="Да",C5>0,E5<>"Продано"),ROUND(C5*'Прайс'!$B$3,0),0) | M5: {=IF(I5<>"",INDEX('Каталог'!$F:$F,MATCH(I5,'Каталог'!$A:$A,0)),"")} | N5: =IF(AND(E5<>"Продано",OR(K5>0,M5>0)),IFERROR(K5,0)+IFERROR(M5,0)+IFERROR(L5,0),"")
A6: 1467 | B6: Цветочная | E6: Продано | F6: Нет | G6: — | H6: — | J6: {=IF(I6<>"",ROUND(INDEX('Каталог'!$F:$F,MATCH(I6,'Каталог'!$A:$A,0))/'Прайс'!$B$4,0),IFERROR(VLOOKUP(D6,'Прайс'!$A$7:$B$9,2,FALSE),'Прайс'!$B$2))} | K6: =IF(AND(C6>0,J6>0,E6<>"Продано"),ROUND(C6*J6,0),"") | L6: =IF(AND(F6="Да",C6>0,E6<>"Продано"),ROUND(C6*'Прайс'!$B$3,0),0) | M6: {=IF(I6<>"",INDEX('Каталог'!$F:$F,MATCH(I6,'Каталог'!$A:$A,0)),"")} | N6: =IF(AND(E6<>"Продано",OR(K6>0,M6>0)),IFERROR(K6,0)+IFERROR(M6,0)+IFERROR(L6,0),"")
A7: 1468 | B7: Цветочная | E7: Продано | F7: Нет | G7: — | H7: — | J7: {=IF(I7<>"",ROUND(INDEX('Каталог'!$F:$F,MATCH(I7,'Каталог'!$A:$A,0))/'Прайс'!$B$4,0),IFERROR(VLOOKUP(D7,'Прайс'!$A$7:$B$9,2,FALSE),'Прайс'!$B$2))} | K7: =IF(AND(C7>0,J7>0,E7<>"Продано"),ROUND(C7*J7,0),"") | L7: =IF(AND(F7="Да",C7>0,E7<>"Продано"),ROUND(C7*'Прайс'!$B$3,0),0) | M7: {=IF(I7<>"",INDEX('Каталог'!$F:$F,MATCH(I7,'Каталог'!$A:$A,0)),"")} | N7: =IF(AND(E7<>"Продано",OR(K7>0,M7>0)),IFERROR(K7,0)+IFERROR(M7,0)+IFERROR(L7,0),"")
A8: 1519 | B8: Корабельная | C8: 563 | E8: Продано | F8: Да | G8: — | H8: — | J8: {=IF(I8<>"",ROUND(INDEX('Каталог'!$F:$F,MATCH(I8,'Каталог'!$A:$A,0))/'Прайс'!$B$4,0),IFERROR(VLOOKUP(D8,'Прайс'!$A$7:$B$9,2,FALSE),'Прайс'!$B$2))} | K8: =IF(AND(C8>0,J8>0,E8<>"Продано"),ROUND(C8*J8,0),"") | L8: =IF(AND(F8="Да",C8>0,E8<>"Продано"),ROUND(C8*'Прайс'!$B$3,0),0) | M8: {=IF(I8<>"",INDEX('Каталог'!$F:$F,MATCH(I8,'Каталог'!$A:$A,0)),"")} | N8: =IF(AND(E8<>"Продано",OR(K8>0,M8>0)),IFERROR(K8,0)+IFERROR(M8,0)+IFERROR(L8,0),"")
A9: 1520 | B9: Корабельная | C9: 561 | E9: Продано | F9: Да | G9: — | H9: — | J9: {=IF(I9<>"",ROUND(INDEX('Каталог'!$F:$F,MATCH(I9,'Каталог'!$A:$A,0))/'Прайс'!$B$4,0),IFERROR(VLOOKUP(D9,'Прайс'!$A$7:$B$9,2,FALSE),'Прайс'!$B$2))} | K9: =IF(AND(C9>0,J9>0,E9<>"Продано"),ROUND(C9*J9,0),"") | L9: =IF(AND(F9="Да",C9>0,E9<>"Продано"),ROUND(C9*'Прайс'!$B$3,0),0) | M9: {=IF(I9<>"",INDEX('Каталог'!$F:$F,MATCH(I9,'Каталог'!$A:$A,0)),"")} | N9: =IF(AND(E9<>"Продано",OR(K9>0,M9>0)),IFERROR(K9,0)+IFERROR(M9,0)+IFERROR(L9,0),"")
A10: 1538 | B10: Айвазовского | C10: 700 | D10: Виноградники / лиман / вулканы | E10: Свободно | F10: Да | G10: 1 ф ВЛВ / 2 ф ВЛВ | H10: 1 эт.: Костеро, Линия 40, Линия 72, Логос, Логос мини, Арбор, Баня | 2 эт.: Палаццо, Эдем, Вилла Маре | J10: {=IF(I10<>"",ROUND(INDEX('Каталог'!$F:$F,MATCH(I10,'Каталог'!$A:$A,0))/'Прайс'!$B$4,0),IFERROR(VLOOKUP(D10,'Прайс'!$A$7:$B$9,2,FALSE),'Прайс'!$B$2))} | K10: =IF(AND(C10>0,J10>0,E10<>"Продано"),ROUND(C10*J10,0),"") | L10: =IF(AND(F10="Да",C10>0,E10<>"Продано"),ROUND(C10*'Прайс'!$B$3,0),0) | M10: {=IF(I10<>"",INDEX('Каталог'!$F:$F,MATCH(I10,'Каталог'!$A:$A,0)),"")} | N10: =IF(AND(E10<>"Продано",OR(K10>0,M10>0)),IFERROR(K10,0)+IFERROR(M10,0)+IFERROR(L10,0),"")
A11: 1539 | B11: Айвазовского | C11: 500 | D11: Вид на море | E11: Свободно | F11: Нет | G11: 1 ф М / 2 ф М | H11: 1 эт.: Костеро, Линия 40, Линия 72, Логос, Логос мини, Арбор, Баня | 2 эт.: Палаццо, Эдем, Вилла Маре | J11: {=IF(I11<>"",ROUND(INDEX('Каталог'!$F:$F,MATCH(I11,'Каталог'!$A:$A,0))/'Прайс'!$B$4,0),IFERROR(VLOOKUP(D11,'Прайс'!$A$7:$B$9,2,FALSE),'Прайс'!$B$2))} | K11: =IF(AND(C11>0,J11>0,E11<>"Продано"),ROUND(C11*J11,0),"") | L11: =IF(AND(F11="Да",C11>0,E11<>"Продано"),ROUND(C11*'Прайс'!$B$3,0),0) | M11: {=IF(I11<>"",INDEX('Каталог'!$F:$F,MATCH(I11,'Каталог'!$A:$A,0)),"")} | N11: =IF(AND(E11<>"Продано",OR(K11>0,M11>0)),IFERROR(K11,0)+IFERROR(M11,0)+IFERROR(L11,0),"")
A12: 1540 | B12: Айвазовского | C12: 500 | D12: Вид на море | E12: Свободно | F12: Нет | G12: 1 ф М / 2 ф М | H12: 1 эт.: Костеро, Линия 40, Линия 72, Логос, Логос мини, Арбор, Баня | 2 эт.: Палаццо, Эдем, Вилла Маре | J12: {=IF(I12<>"",ROUND(INDEX('Каталог'!$F:$F,MATCH(I12,'Каталог'!$A:$A,0))/'Прайс'!$B$4,0),IFERROR(VLOOKUP(D12,'Прайс'!$A$7:$B$9,2,FALSE),'Прайс'!$B$2))} | K12: =IF(AND(C12>0,J12>0,E12<>"Продано"),ROUND(C12*J12,0),"") | L12: =IF(AND(F12="Да",C12>0,E12<>"Продано"),ROUND(C12*'Прайс'!$B$3,0),0) | M12: {=IF(I12<>"",INDEX('Каталог'!$F:$F,MATCH(I12,'Каталог'!$A:$A,0)),"")} | N12: =IF(AND(E12<>"Продано",OR(K12>0,M12>0)),IFERROR(K12,0)+IFERROR(M12,0)+IFERROR(L12,0),"")
A13: 1541 | B13: Айвазовского | C13: 500 | D13: Вид на море | E13: Свободно | F13: Нет | G13: 1 ф М / 2 ф М | H13: 1 эт.: Костеро, Линия 40, Линия 72, Логос, Логос мини, Арбор, Баня | 2 эт.: Палаццо, Эдем, Вилла Маре | J13: {=IF(I13<>"",ROUND(INDEX('Каталог'!$F:$F,MATCH(I13,'Каталог'!$A:$A,0))/'Прайс'!$B$4,0),IFERROR(VLOOKUP(D13,'Прайс'!$A$7:$B$9,2,FALSE),'Прайс'!$B$2))} | K13: =IF(AND(C13>0,J13>0,E13<>"Продано"),ROUND(C13*J13,0),"") | L13: =IF(AND(F13="Да",C13>0,E13<>"Продано"),ROUND(C13*'Прайс'!$B$3,0),0) | M13: {=IF(I13<>"",INDEX('Каталог'!$F:$F,MATCH(I13,'Каталог'!$A:$A,0)),"")} | N13: =IF(AND(E13<>"Продано",OR(K13>0,M13>0)),IFERROR(K13,0)+IFERROR(M13,0)+IFERROR(L13,0),"")
A14: 1542 | B14: Айвазовского | C14: 500 | D14: Вид на море | E14: Свободно | F14: Нет | G14: 1 ф М / 2 ф М | H14: 1 эт.: Костеро, Линия 40, Линия 72, Логос, Логос мини, Арбор, Баня | 2 эт.: Палаццо, Эдем, Вилла Маре | J14: {=IF(I14<>"",ROUND(INDEX('Каталог'!$F:$F,MATCH(I14,'Каталог'!$A:$A,0))/'Прайс'!$B$4,0),IFERROR(VLOOKUP(D14,'Прайс'!$A$7:$B$9,2,FALSE),'Прайс'!$B$2))} | K14: =IF(AND(C14>0,J14>0,E14<>"Продано"),ROUND(C14*J14,0),"") | L14: =IF(AND(F14="Да",C14>0,E14<>"Продано"),ROUND(C14*'Прайс'!$B$3,0),0) | M14: {=IF(I14<>"",INDEX('Каталог'!$F:$F,MATCH(I14,'Каталог'!$A:$A,0)),"")} | N14: =IF(AND(E14<>"Продано",OR(K14>0,M14>0)),IFERROR(K14,0)+IFERROR(M14,0)+IFERROR(L14,0),"")
A15: 1543 | B15: Айвазовского | C15: 500 | D15: Вид на море | E15: Свободно | F15: Нет | G15: 1 ф М / 2 ф М | H15: 1 эт.: Костеро, Линия 40, Линия 72, Логос, Логос мини, Арбор, Баня | 2 эт.: Палаццо, Эдем, Вилла Маре | J15: {=IF(I15<>"",ROUND(INDEX('Каталог'!$F:$F,MATCH(I15,'Каталог'!$A:$A,0))/'Прайс'!$B$4,0),IFERROR(VLOOKUP(D15,'Прайс'!$A$7:$B$9,2,FALSE),'Прайс'!$B$2))} | K15: =IF(AND(C15>0,J15>0,E15<>"Продано"),ROUND(C15*J15,0),"") | L15: =IF(AND(F15="Да",C15>0,E15<>"Продано"),ROUND(C15*'Прайс'!$B$3,0),0) | M15: {=IF(I15<>"",INDEX('Каталог'!$F:$F,MATCH(I15,'Каталог'!$A:$A,0)),"")} | N15: =IF(AND(E15<>"Продано",OR(K15>0,M15>0)),IFERROR(K15,0)+IFERROR(M15,0)+IFERROR(L15,0),"")
A16: 1544 | B16: Айвазовского | C16: 500 | D16: Вид на море | E16: Свободно | F16: Нет | G16: 1 ф М / 2 ф М | H16: 1 эт.: Костеро, Линия 40, Линия 72, Логос, Логос мини, Арбор, Баня | 2 эт.: Палаццо, Эдем, Вилла Маре | J16: {=IF(I16<>"",ROUND(INDEX('Каталог'!$F:$F,MATCH(I16,'Каталог'!$A:$A,0))/'Прайс'!$B$4,0),IFERROR(VLOOKUP(D16,'Прайс'!$A$7:$B$9,2,FALSE),'Прайс'!$B$2))} | K16: =IF(AND(C16>0,J16>0,E16<>"Продано"),ROUND(C16*J16,0),"") | L16: =IF(AND(F16="Да",C16>0,E16<>"Продано"),ROUND(C16*'Прайс'!$B$3,0),0) | M16: {=IF(I16<>"",INDEX('Каталог'!$F:$F,MATCH(I16,'Каталог'!$A:$A,0)),"")} | N16: =IF(AND(E16<>"Продано",OR(K16>0,M16>0)),IFERROR(K16,0)+IFERROR(M16,0)+IFERROR(L16,0),"")
A17: 1545 | B17: Айвазовского | C17: 700 | D17: Вид на море | E17: Свободно | F17: Да | G17: 1 ф М / 2 ф М | H17: 1 эт.: Костеро, Линия 40, Линия 72, Логос, Логос мини, Арбор, Баня | 2 эт.: Палаццо, Эдем, Вилла Маре | J17: {=IF(I17<>"",ROUND(INDEX('Каталог'!$F:$F,MATCH(I17,'Каталог'!$A:$A,0))/'Прайс'!$B$4,0),IFERROR(VLOOKUP(D17,'Прайс'!$A$7:$B$9,2,FALSE),'Прайс'!$B$2))} | K17: =IF(AND(C17>0,J17>0,E17<>"Продано"),ROUND(C17*J17,0),"") | L17: =IF(AND(F17="Да",C17>0,E17<>"Продано"),ROUND(C17*'Прайс'!$B$3,0),0) | M17: {=IF(I17<>"",INDEX('Каталог'!$F:$F,MATCH(I17,'Каталог'!$A:$A,0)),"")} | N17: =IF(AND(E17<>"Продано",OR(K17>0,M17>0)),IFERROR(K17,0)+IFERROR(M17,0)+IFERROR(L17,0),"")
A18: 1546 | B18: Айвазовского | C18: 500 | D18: Виноградники / лиман / вулканы | E18: Свободно | F18: Нет | G18: 1 ф ВЛВ / 2 ф ВЛВ | H18: 1 эт.: Костеро, Линия 40, Линия 72, Логос, Логос мини, Арбор, Баня | 2 эт.: Палаццо, Эдем, Вилла Маре | J18: {=IF(I18<>"",ROUND(INDEX('Каталог'!$F:$F,MATCH(I18,'Каталог'!$A:$A,0))/'Прайс'!$B$4,0),IFERROR(VLOOKUP(D18,'Прайс'!$A$7:$B$9,2,FALSE),'Прайс'!$B$2))} | K18: =IF(AND(C18>0,J18>0,E18<>"Продано"),ROUND(C18*J18,0),"") | L18: =IF(AND(F18="Да",C18>0,E18<>"Продано"),ROUND(C18*'Прайс'!$B$3,0),0) | M18: {=IF(I18<>"",INDEX('Каталог'!$F:$F,MATCH(I18,'Каталог'!$A:$A,0)),"")} | N18: =IF(AND(E18<>"Продано",OR(K18>0,M18>0)),IFERROR(K18,0)+IFERROR(M18,0)+IFERROR(L18,0),"")
A19: 1547 | B19: Айвазовского | C19: 500 | D19: Виноградники / лиман / вулканы | E19: Свободно | F19: Нет | G19: 1 ф ВЛВ / 2 ф ВЛВ | H19: 1 эт.: Костеро, Линия 40, Линия 72, Логос, Логос мини, Арбор, Баня | 2 эт.: Палаццо, Эдем, Вилла Маре | J19: {=IF(I19<>"",ROUND(INDEX('Каталог'!$F:$F,MATCH(I19,'Каталог'!$A:$A,0))/'Прайс'!$B$4,0),IFERROR(VLOOKUP(D19,'Прайс'!$A$7:$B$9,2,FALSE),'Прайс'!$B$2))} | K19: =IF(AND(C19>0,J19>0,E19<>"Продано"),ROUND(C19*J19,0),"") | L19: =IF(AND(F19="Да",C19>0,E19<>"Продано"),ROUND(C19*'Прайс'!$B$3,0),0) | M19: {=IF(I19<>"",INDEX('Каталог'!$F:$F,MATCH(I19,'Каталог'!$A:$A,0)),"")} | N19: =IF(AND(E19<>"Продано",OR(K19>0,M19>0)),IFERROR(K19,0)+IFERROR(M19,0)+IFERROR(L19,0),"")
A20: 1548 | B20: Айвазовского | C20: 500 | D20: Виноградники / лиман / вулканы | E20: Свободно | F20: Нет | G20: 1 ф ВЛВ / 2 ф ВЛВ | H20: 1 эт.: Костеро, Линия 40, Линия 72, Логос, Логос мини, Арбор, Баня | 2 эт.: Палаццо, Эдем, Вилла Маре | J20: {=IF(I20<>"",ROUND(INDEX('Каталог'!$F:$F,MATCH(I20,'Каталог'!$A:$A,0))/'Прайс'!$B$4,0),IFERROR(VLOOKUP(D20,'Прайс'!$A$7:$B$9,2,FALSE),'Прайс'!$B$2))} | K20: =IF(AND(C20>0,J20>0,E20<>"Продано"),ROUND(C20*J20,0),"") | L20: =IF(AND(F20="Да",C20>0,E20<>"Продано"),ROUND(C20*'Прайс'!$B$3,0),0) | M20: {=IF(I20<>"",INDEX('Каталог'!$F:$F,MATCH(I20,'Каталог'!$A:$A,0)),"")} | N20: =IF(AND(E20<>"Продано",OR(K20>0,M20>0)),IFERROR(K20,0)+IFERROR(M20,0)+IFERROR(L20,0),"")
A21: 1549 | B21: Айвазовского | C21: 500 | D21: Виноградники / лиман / вулканы | E21: Свободно | F21: Нет | G21: 1 ф ВЛВ / 2 ф ВЛВ | H21: 1 эт.: Костеро, Линия 40, Линия 72, Логос, Логос мини, Арбор, Баня | 2 эт.: Палаццо, Эдем, Вилла Маре | J21: {=IF(I21<>"",ROUND(INDEX('Каталог'!$F:$F,MATCH(I21,'Каталог'!$A:$A,0))/'Прайс'!$B$4,0),IFERROR(VLOOKUP(D21,'Прайс'!$A$7:$B$9,2,FALSE),'Прайс'!$B$2))} | K21: =IF(AND(C21>0,J21>0,E21<>"Продано"),ROUND(C21*J21,0),"") | L21: =IF(AND(F21="Да",C21>0,E21<>"Продано"),ROUND(C21*'Прайс'!$B$3,0),0) | M21: {=IF(I21<>"",INDEX('Каталог'!$F:$F,MATCH(I21,'Каталог'!$A:$A,0)),"")} | N21: =IF(AND(E21<>"Продано",OR(K21>0,M21>0)),IFERROR(K21,0)+IFERROR(M21,0)+IFERROR(L21,0),"")
... A25: 1553 | B25: Айвазовского | C25: 783 | D25: Вид на море | E25: Свободно | F25: Да | G25: 1 ф М / 2 ф М | H25: 1 эт.: Костеро, Линия 40, Линия 72, Логос, Логос мини, Арбор, Баня | 2 эт.: Палаццо, Эдем, Вилла Маре | J25: {=IF(I25<>"",ROUND(INDEX('Каталог'!$F:$F,MATCH(I25,'Каталог'!$A:$A,0))/'Прайс'!$B$4,0),IFERROR(VLOOKUP(D25,'Прайс'!$A$7:$B$9,2,FALSE),'Прайс'!$B$2))} | K25: =IF(AND(C25>0,J25>0,E25<>"Продано"),ROUND(C25*J25,0),"") | L25: =IF(AND(F25="Да",C25>0,E25<>"Продано"),ROUND(C25*'Прайс'!$B$3,0),0) | M25: {=IF(I25<>"",INDEX('Каталог'!$F:$F,MATCH(I25,'Каталог'!$A:$A,0)),"")} | N25: =IF(AND(E25<>"Продано",OR(K25>0,M25>0)),IFERROR(K25,0)+IFERROR(M25,0)+IFERROR(L25,0),"")
A26: 1555 | B26: Корабельная | E26: Продано | F26: Нет | G26: — | H26: — | J26: {=IF(I26<>"",ROUND(INDEX('Каталог'!$F:$F,MATCH(I26,'Каталог'!$A:$A,0))/'Прайс'!$B$4,0),IFERROR(VLOOKUP(D26,'Прайс'!$A$7:$B$9,2,FALSE),'Прайс'!$B$2))} | K26: =IF(AND(C26>0,J26>0,E26<>"Продано"),ROUND(C26*J26,0),"") | L26: =IF(AND(F26="Да",C26>0,E26<>"Продано"),ROUND(C26*'Прайс'!$B$3,0),0) | M26: {=IF(I26<>"",INDEX('Каталог'!$F:$F,MATCH(I26,'Каталог'!$A:$A,0)),"")} | N26: =IF(AND(E26<>"Продано",OR(K26>0,M26>0)),IFERROR(K26,0)+IFERROR(M26,0)+IFERROR(L26,0),"")
A27: 1556 | B27: Корабельная | E27: Продано | F27: Нет | G27: — | H27: — | J27: {=IF(I27<>"",ROUND(INDEX('Каталог'!$F:$F,MATCH(I27,'Каталог'!$A:$A,0))/'Прайс'!$B$4,0),IFERROR(VLOOKUP(D27,'Прайс'!$A$7:$B$9,2,FALSE),'Прайс'!$B$2))} | K27: =IF(AND(C27>0,J27>0,E27<>"Продано"),ROUND(C27*J27,0),"") | L27: =IF(AND(F27="Да",C27>0,E27<>"Продано"),ROUND(C27*'Прайс'!$B$3,0),0) | M27: {=IF(I27<>"",INDEX('Каталог'!$F:$F,MATCH(I27,'Каталог'!$A:$A,0)),"")} | N27: =IF(AND(E27<>"Продано",OR(K27>0,M27>0)),IFERROR(K27,0)+IFERROR(M27,0)+IFERROR(L27,0),"")
A28: 1557 | B28: Корабельная | E28: Продано | F28: Нет | G28: — | H28: — | J28: {=IF(I28<>"",ROUND(INDEX('Каталог'!$F:$F,MATCH(I28,'Каталог'!$A:$A,0))/'Прайс'!$B$4,0),IFERROR(VLOOKUP(D28,'Прайс'!$A$7:$B$9,2,FALSE),'Прайс'!$B$2))} | K28: =IF(AND(C28>0,J28>0,E28<>"Продано"),ROUND(C28*J28,0),"") | L28: =IF(AND(F28="Да",C28>0,E28<>"Продано"),ROUND(C28*'Прайс'!$B$3,0),0) | M28: {=IF(I28<>"",INDEX('Каталог'!$F:$F,MATCH(I28,'Каталог'!$A:$A,0)),"")} | N28: =IF(AND(E28<>"Продано",OR(K28>0,M28>0)),IFERROR(K28,0)+IFERROR(M28,0)+IFERROR(L28,0),"")
A29: 1561 | B29: Корабельная | E29: Продано | F29: Нет | G29: — | H29: — | J29: {=IF(I29<>"",ROUND(INDEX('Каталог'!$F:$F,MATCH(I29,'Каталог'!$A:$A,0))/'Прайс'!$B$4,0),IFERROR(VLOOKUP(D29,'Прайс'!$A$7:$B$9,2,FALSE),'Прайс'!$B$2))} | K29: =IF(AND(C29>0,J29>0,E29<>"Продано"),ROUND(C29*J29,0),"") | L29: =IF(AND(F29="Да",C29>0,E29<>"Продано"),ROUND(C29*'Прайс'!$B$3,0),0) | M29: {=IF(I29<>"",INDEX('Каталог'!$F:$F,MATCH(I29,'Каталог'!$A:$A,0)),"")} | N29: =IF(AND(E29<>"Продано",OR(K29>0,M29>0)),IFERROR(K29,0)+IFERROR(M29,0)+IFERROR(L29,0),"")
A30: 1569 | B30: Корабельная | C30: 500 | E30: Продано | F30: Нет | G30: — | H30: — | J30: {=IF(I30<>"",ROUND(INDEX('Каталог'!$F:$F,MATCH(I30,'Каталог'!$A:$A,0))/'Прайс'!$B$4,0),IFERROR(VLOOKUP(D30,'Прайс'!$A$7:$B$9,2,FALSE),'Прайс'!$B$2))} | K30: =IF(AND(C30>0,J30>0,E30<>"Продано"),ROUND(C30*J30,0),"") | L30: =IF(AND(F30="Да",C30>0,E30<>"Продано"),ROUND(C30*'Прайс'!$B$3,0),0) | M30: {=IF(I30<>"",INDEX('Каталог'!$F:$F,MATCH(I30,'Каталог'!$A:$A,0)),"")} | N30: =IF(AND(E30<>"Продано",OR(K30>0,M30>0)),IFERROR(K30,0)+IFERROR(M30,0)+IFERROR(L30,0),"")
A31: 1570 | B31: Корабельная | C31: 500 | E31: Продано | F31: Нет | G31: — | H31: — | J31: {=IF(I31<>"",ROUND(INDEX('Каталог'!$F:$F,MATCH(I31,'Каталог'!$A:$A,0))/'Прайс'!$B$4,0),IFERROR(VLOOKUP(D31,'Прайс'!$A$7:$B$9,2,FALSE),'Прайс'!$B$2))} | K31: =IF(AND(C31>0,J31>0,E31<>"Продано"),ROUND(C31*J31,0),"") | L31: =IF(AND(F31="Да",C31>0,E31<>"Продано"),ROUND(C31*'Прайс'!$B$3,0),0) | M31: {=IF(I31<>"",INDEX('Каталог'!$F:$F,MATCH(I31,'Каталог'!$A:$A,0)),"")} | N31: =IF(AND(E31<>"Продано",OR(K31>0,M31>0)),IFERROR(K31,0)+IFERROR(M31,0)+IFERROR(L31,0),"")
A32: 1571 | B32: Корабельная | E32: Продано | F32: Нет | G32: — | H32: — | J32: {=IF(I32<>"",ROUND(INDEX('Каталог'!$F:$F,MATCH(I32,'Каталог'!$A:$A,0))/'Прайс'!$B$4,0),IFERROR(VLOOKUP(D32,'Прайс'!$A$7:$B$9,2,FALSE),'Прайс'!$B$2))} | K32: =IF(AND(C32>0,J32>0,E32<>"Продано"),ROUND(C32*J32,0),"") | L32: =IF(AND(F32="Да",C32>0,E32<>"Продано"),ROUND(C32*'Прайс'!$B$3,0),0) | M32: {=IF(I32<>"",INDEX('Каталог'!$F:$F,MATCH(I32,'Каталог'!$A:$A,0)),"")} | N32: =IF(AND(E32<>"Продано",OR(K32>0,M32>0)),IFERROR(K32,0)+IFERROR(M32,0)+IFERROR(L32,0),"")
A33: 1572 | B33: Айвазовского | C33: 500 | D33: Виноградники / лиман / вулканы | E33: Свободно | F33: Нет | G33: 1 ф ВЛВ / 2 ф ВЛВ | H33: 1 эт.: Костеро, Линия 40, Линия 72, Логос, Логос мини, Арбор, Баня | 2 эт.: Палаццо, Эдем, Вилла Маре | J33: {=IF(I33<>"",ROUND(INDEX('Каталог'!$F:$F,MATCH(I33,'Каталог'!$A:$A,0))/'Прайс'!$B$4,0),IFERROR(VLOOKUP(D33,'Прайс'!$A$7:$B$9,2,FALSE),'Прайс'!$B$2))} | K33: =IF(AND(C33>0,J33>0,E33<>"Продано"),ROUND(C33*J33,0),"") | L33: =IF(AND(F33="Да",C33>0,E33<>"Продано"),ROUND(C33*'Прайс'!$B$3,0),0) | M33: {=IF(I33<>"",INDEX('Каталог'!$F:$F,MATCH(I33,'Каталог'!$A:$A,0)),"")} | N33: =IF(AND(E33<>"Продано",OR(K33>0,M33>0)),IFERROR(K33,0)+IFERROR(M33,0)+IFERROR(L33,0),"")
A34: 1573 | B34: Айвазовского | E34: Резерв | F34: Нет | G34: — | H34: — | J34: {=IF(I34<>"",ROUND(INDEX('Каталог'!$F:$F,MATCH(I34,'Каталог'!$A:$A,0))/'Прайс'!$B$4,0),IFERROR(VLOOKUP(D34,'Прайс'!$A$7:$B$9,2,FALSE),'Прайс'!$B$2))} | K34: =IF(AND(C34>0,J34>0,E34<>"Продано"),ROUND(C34*J34,0),"") | L34: =IF(AND(F34="Да",C34>0,E34<>"Продано"),ROUND(C34*'Прайс'!$B$3,0),0) | M34: {=IF(I34<>"",INDEX('Каталог'!$F:$F,MATCH(I34,'Каталог'!$A:$A,0)),"")} | N34: =IF(AND(E34<>"Продано",OR(K34>0,M34>0)),IFERROR(K34,0)+IFERROR(M34,0)+IFERROR(L34,0),"")
A35: 1574 | B35: Айвазовского | D35: Виноградники / лиман / вулканы | E35: Свободно | F35: Нет | G35: 1 ф ВЛВ / 2 ф ВЛВ | H35: 1 эт.: Костеро, Линия 40, Линия 72, Логос, Логос мини, Арбор, Баня | 2 эт.: Палаццо, Эдем, Вилла Маре | J35: {=IF(I35<>"",ROUND(INDEX('Каталог'!$F:$F,MATCH(I35,'Каталог'!$A:$A,0))/'Прайс'!$B$4,0),IFERROR(VLOOKUP(D35,'Прайс'!$A$7:$B$9,2,FALSE),'Прайс'!$B$2))} | K35: =IF(AND(C35>0,J35>0,E35<>"Продано"),ROUND(C35*J35,0),"") | L35: =IF(AND(F35="Да",C35>0,E35<>"Продано"),ROUND(C35*'Прайс'!$B$3,0),0) | M35: {=IF(I35<>"",INDEX('Каталог'!$F:$F,MATCH(I35,'Каталог'!$A:$A,0)),"")} | N35: =IF(AND(E35<>"Продано",OR(K35>0,M35>0)),IFERROR(K35,0)+IFERROR(M35,0)+IFERROR(L35,0),"")
A36: 1575 | B36: Айвазовского | D36: Вид на море | E36: Свободно | F36: Нет | G36: 1 ф М / 2 ф М | H36: 1 эт.: Костеро, Линия 40, Линия 72, Логос, Логос мини, Арбор, Баня | 2 эт.: Палаццо, Эдем, Вилла Маре | J36: {=IF(I36<>"",ROUND(INDEX('Каталог'!$F:$F,MATCH(I36,'Каталог'!$A:$A,0))/'Прайс'!$B$4,0),IFERROR(VLOOKUP(D36,'Прайс'!$A$7:$B$9,2,FALSE),'Прайс'!$B$2))} | K36: =IF(AND(C36>0,J36>0,E36<>"Продано"),ROUND(C36*J36,0),"") | L36: =IF(AND(F36="Да",C36>0,E36<>"Продано"),ROUND(C36*'Прайс'!$B$3,0),0) | M36: {=IF(I36<>"",INDEX('Каталог'!$F:$F,MATCH(I36,'Каталог'!$A:$A,0)),"")} | N36: =IF(AND(E36<>"Продано",OR(K36>0,M36>0)),IFERROR(K36,0)+IFERROR(M36,0)+IFERROR(L36,0),"")
A37: 1576 | B37: Айвазовского | D37: Вид на море | E37: Свободно | F37: Нет | G37: 1 ф М / 2 ф М | H37: 1 эт.: Костеро, Линия 40, Линия 72, Логос, Логос мини, Арбор, Баня | 2 эт.: Палаццо, Эдем, Вилла Маре | J37: {=IF(I37<>"",ROUND(INDEX('Каталог'!$F:$F,MATCH(I37,'Каталог'!$A:$A,0))/'Прайс'!$B$4,0),IFERROR(VLOOKUP(D37,'Прайс'!$A$7:$B$9,2,FALSE),'Прайс'!$B$2))} | K37: =IF(AND(C37>0,J37>0,E37<>"Продано"),ROUND(C37*J37,0),"") | L37: =IF(AND(F37="Да",C37>0,E37<>"Продано"),ROUND(C37*'Прайс'!$B$3,0),0) | M37: {=IF(I37<>"",INDEX('Каталог'!$F:$F,MATCH(I37,'Каталог'!$A:$A,0)),"")} | N37: =IF(AND(E37<>"Продано",OR(K37>0,M37>0)),IFERROR(K37,0)+IFERROR(M37,0)+IFERROR(L37,0),"")
A38: 1577 | B38: Айвазовского | D38: Вид на море | E38: Свободно | F38: Нет | G38: 1 ф М / 2 ф М | H38: 1 эт.: Костеро, Линия 40, Линия 72, Логос, Логос мини, Арбор, Баня | 2 эт.: Палаццо, Эдем, Вилла Маре | J38: {=IF(I38<>"",ROUND(INDEX('Каталог'!$F:$F,MATCH(I38,'Каталог'!$A:$A,0))/'Прайс'!$B$4,0),IFERROR(VLOOKUP(D38,'Прайс'!$A$7:$B$9,2,FALSE),'Прайс'!$B$2))} | K38: =IF(AND(C38>0,J38>0,E38<>"Продано"),ROUND(C38*J38,0),"") | L38: =IF(AND(F38="Да",C38>0,E38<>"Продано"),ROUND(C38*'Прайс'!$B$3,0),0) | M38: {=IF(I38<>"",INDEX('Каталог'!$F:$F,MATCH(I38,'Каталог'!$A:$A,0)),"")} | N38: =IF(AND(E38<>"Продано",OR(K38>0,M38>0)),IFERROR(K38,0)+IFERROR(M38,0)+IFERROR(L38,0),"")
A39: 1578 | B39: Айвазовского | D39: Вид на море | E39: Свободно | F39: Нет | G39: 1 ф М / 2 ф М | H39: 1 эт.: Костеро, Линия 40, Линия 72, Логос, Логос мини, Арбор, Баня | 2 эт.: Палаццо, Эдем, Вилла Маре | J39: {=IF(I39<>"",ROUND(INDEX('Каталог'!$F:$F,MATCH(I39,'Каталог'!$A:$A,0))/'Прайс'!$B$4,0),IFERROR(VLOOKUP(D39,'Прайс'!$A$7:$B$9,2,FALSE),'Прайс'!$B$2))} | K39: =IF(AND(C39>0,J39>0,E39<>"Продано"),ROUND(C39*J39,0),"") | L39: =IF(AND(F39="Да",C39>0,E39<>"Продано"),ROUND(C39*'Прайс'!$B$3,0),0) | M39: {=IF(I39<>"",INDEX('Каталог'!$F:$F,MATCH(I39,'Каталог'!$A:$A,0)),"")} | N39: =IF(AND(E39<>"Продано",OR(K39>0,M39>0)),IFERROR(K39,0)+IFERROR(M39,0)+IFERROR(L39,0),"")
A40: 1579 | B40: Айвазовского | D40: Вид на море | E40: Свободно | F40: Нет | G40: 1 ф М / 2 ф М | H40: 1 эт.: Костеро, Линия 40, Линия 72, Логос, Логос мини, Арбор, Баня | 2 эт.: Палаццо, Эдем, Вилла Маре | J40: {=IF(I40<>"",ROUND(INDEX('Каталог'!$F:$F,MATCH(I40,'Каталог'!$A:$A,0))/'Прайс'!$B$4,0),IFERROR(VLOOKUP(D40,'Прайс'!$A$7:$B$9,2,FALSE),'Прайс'!$B$2))} | K40: =IF(AND(C40>0,J40>0,E40<>"Продано"),ROUND(C40*J40,0),"") | L40: =IF(AND(F40="Да",C40>0,E40<>"Продано"),ROUND(C40*'Прайс'!$B$3,0),0) | M40: {=IF(I40<>"",INDEX('Каталог'!$F:$F,MATCH(I40,'Каталог'!$A:$A,0)),"")} | N40: =IF(AND(E40<>"Продано",OR(K40>0,M40>0)),IFERROR(K40,0)+IFERROR(M40,0)+IFERROR(L40,0),"")
A41: 1580 | B41: Айвазовского | D41: Вид на море | E41: Свободно | F41: Нет | G41: 1 ф М / 2 ф М | H41: 1 эт.: Костеро, Линия 40, Линия 72, Логос, Логос мини, Арбор, Баня | 2 эт.: Палаццо, Эдем, Вилла Маре | J41: {=IF(I41<>"",ROUND(INDEX('Каталог'!$F:$F,MATCH(I41,'Каталог'!$A:$A,0))/'Прайс'!$B$4,0),IFERROR(VLOOKUP(D41,'Прайс'!$A$7:$B$9,2,FALSE),'Прайс'!$B$2))} | K41: =IF(AND(C41>0,J41>0,E41<>"Продано"),ROUND(C41*J41,0),"") | L41: =IF(AND(F41="Да",C41>0,E41<>"Продано"),ROUND(C41*'Прайс'!$B$3,0),0) | M41: {=IF(I41<>"",INDEX('Каталог'!$F:$F,MATCH(I41,'Каталог'!$A:$A,0)),"")} | N41: =IF(AND(E41<>"Продано",OR(K41>0,M41>0)),IFERROR(K41,0)+IFERROR(M41,0)+IFERROR(L41,0),"")
A42: 1581 | B42: Айвазовского | D42: Вид на море | E42: Свободно | F42: Нет | G42: 1 ф М / 2 ф М | H42: 1 эт.: Костеро, Линия 40, Линия 72, Логос, Логос мини, Арбор, Баня | 2 эт.: Палаццо, Эдем, Вилла Маре | J42: {=IF(I42<>"",ROUND(INDEX('Каталог'!$F:$F,MATCH(I42,'Каталог'!$A:$A,0))/'Прайс'!$B$4,0),IFERROR(VLOOKUP(D42,'Прайс'!$A$7:$B$9,2,FALSE),'Прайс'!$B$2))} | K42: =IF(AND(C42>0,J42>0,E42<>"Продано"),ROUND(C42*J42,0),"") | L42: =IF(AND(F42="Да",C42>0,E42<>"Продано"),ROUND(C42*'Прайс'!$B$3,0),0) | M42: {=IF(I42<>"",INDEX('Каталог'!$F:$F,MATCH(I42,'Каталог'!$A:$A,0)),"")} | N42: =IF(AND(E42<>"Продано",OR(K42>0,M42>0)),IFERROR(K42,0)+IFERROR(M42,0)+IFERROR(L42,0),"")
A43: 1582 | B43: Айвазовского | C43: 500 | D43: Виноградники / лиман / вулканы | E43: Свободно | F43: Нет | G43: 1 ф ВЛВ / 2 ф ВЛВ | H43: 1 эт.: Костеро, Линия 40, Линия 72, Логос, Логос мини, Арбор, Баня | 2 эт.: Палаццо, Эдем, Вилла Маре | J43: {=IF(I43<>"",ROUND(INDEX('Каталог'!$F:$F,MATCH(I43,'Каталог'!$A:$A,0))/'Прайс'!$B$4,0),IFERROR(VLOOKUP(D43,'Прайс'!$A$7:$B$9,2,FALSE),'Прайс'!$B$2))} | K43: =IF(AND(C43>0,J43>0,E43<>"Продано"),ROUND(C43*J43,0),"") | L43: =IF(AND(F43="Да",C43>0,E43<>"Продано"),ROUND(C43*'Прайс'!$B$3,0),0) | M43: {=IF(I43<>"",INDEX('Каталог'!$F:$F,MATCH(I43,'Каталог'!$A:$A,0)),"")} | N43: =IF(AND(E43<>"Продано",OR(K43>0,M43>0)),IFERROR(K43,0)+IFERROR(M43,0)+IFERROR(L43,0),"")
...

Sheet Данные SPACE
A1: № | B1: Тип | C1: Дом м² | D1: Участок сот | E1: Вид | F1: Цена | G1: ₽/м² | H1: Статус
A2: № 1 | B2: БАРНХАУС | C2: 62 | G2: =IF(AND(F2>0,C2>0),ROUND(F2/C2,0),"") | H2: Продано
A3: № 2 | B3: А-ФРЕЙМ | C3: 40 | G3: =IF(AND(F3>0,C3>0),ROUND(F3/C3,0),"") | H3: Продано
A4: № 3 | B4: А-ФРЕЙМ | C4: 40 | G4: =IF(AND(F4>0,C4>0),ROUND(F4/C4,0),"") | H4: Продано
A5: № 4 | B5: А-ФРЕЙМ | C5: 40 | F5: 14500000 | G5: =IF(AND(F5>0,C5>0),ROUND(F5/C5,0),"") | H5: Свободно (акция)
A6: № 5 | B6: А-ФРЕЙМ | C6: 40 | G6: =IF(AND(F6>0,C6>0),ROUND(F6/C6,0),"") | H6: Продано
A7: № 6 | B7: БАРНХАУС | C7: 62 | G7: =IF(AND(F7>0,C7>0),ROUND(F7/C7,0),"") | H7: Продано
A8: № 7 | B8: А-ФРЕЙМ | C8: 40 | F8: 12000000 | G8: =IF(AND(F8>0,C8>0),ROUND(F8/C8,0),"") | H8: Свободно
A9: № 8 | B9: А-ФРЕЙМ | C9: 40 | F9: 12000000 | G9: =IF(AND(F9>0,C9>0),ROUND(F9/C9,0),"") | H9: Свободно
A10: № 9 | B10: А-ФРЕЙМ | C10: 40 | F10: 12000000 | G10: =IF(AND(F10>0,C10>0),ROUND(F10/C10,0),"") | H10: Свободно
A11: № 10 | B11: А-ФРЕЙМ | C11: 40 | F11: 12000000 | G11: =IF(AND(F11>0,C11>0),ROUND(F11/C11,0),"") | H11: Свободно
A12: № 11 | B12: БАРНХАУС | C12: 62 | F12: 16000000 | G12: =IF(AND(F12>0,C12>0),ROUND(F12/C12,0),"") | H12: Свободно
A13: № 12 | B13: А-ФРЕЙМ | C13: 62 | G13: =IF(AND(F13>0,C13>0),ROUND(F13/C13,0),"") | H13: Продано
A14: № 13 | B14: А-ФРЕЙМ | C14: 40 | F14: 12000000 | G14: =IF(AND(F14>0,C14>0),ROUND(F14/C14,0),"") | H14: Свободно
A15: № 14 | B15: А-ФРЕЙМ | C15: 40 | F15: 12000000 | G15: =IF(AND(F15>0,C15>0),ROUND(F15/C15,0),"") | H15: Свободно
A16: № 15 | B16: А-ФРЕЙМ | C16: 40 | F16: 11500000 | G16: =IF(AND(F16>0,C16>0),ROUND(F16/C16,0),"") | H16: Свободно (акция)
A17: № 16 | B17: БАРНХАУС | C17: 40 | G17: =IF(AND(F17>0,C17>0),ROUND(F17/C17,0),"") | H17: Продано
A18: № 17 | B18: А-ФРЕЙМ | C18: 40 | F18: 12000000 | G18: =IF(AND(F18>0,C18>0),ROUND(F18/C18,0),"") | H18: Свободно
A19: № 18 | B19: А-ФРЕЙМ | C19: 62 | F19: 12000000 | G19: =IF(AND(F19>0,C19>0),ROUND(F19/C19,0),"") | H19: Свободно
A20: № 19 | B20: А-ФРЕЙМ | C20: 40 | G20: =IF(AND(F20>0,C20>0),ROUND(F20/C20,0),"") | H20: Продано
A21: № 20 | B21: А-ФРЕЙМ | C21: 62 | G21: =IF(AND(F21>0,C21>0),ROUND(F21/C21,0),"") | H21: Продано
A22: № 21 | B22: БАРНХАУС | C22: 62 | G22: =IF(AND(F22>0,C22>0),ROUND(F22/C22,0),"") | H22: Продано
A23: № 22 | B23: А-ФРЕЙМ | C23: 40 | F23: 12000000 | G23: =IF(AND(F23>0,C23>0),ROUND(F23/C23,0),"") | H23: Свободно
A24: № 23 | B24: А-ФРЕЙМ | C24: 40 | F24: 12000000 | G24: =IF(AND(F24>0,C24>0),ROUND(F24/C24,0),"") | H24: Свободно
A25: № 24 | B25: А-ФРЕЙМ | C25: 40 | F25: 12000000 | G25: =IF(AND(F25>0,C25>0),ROUND(F25/C25,0),"") | H25: Свободно
A26: № 25 | B26: А-ФРЕЙМ | C26: 40 | F26: 12000000 | G26: =IF(AND(F26>0,C26>0),ROUND(F26/C26,0),"") | H26: Свободно
A27: № 26 | B27: А-ФРЕЙМ | C27: 40 | F27: 12000000 | G27: =IF(AND(F27>0,C27>0),ROUND(F27/C27,0),"") | H27: Свободно
A28: № 27 | B28: БАРНХАУС | C28: 62 | G28: =IF(AND(F28>0,C28>0),ROUND(F28/C28,0),"") | H28: Продано
A29: № 28 | B29: А-ФРЕЙМ | C29: 40 | F29: 12000000 | G29: =IF(AND(F29>0,C29>0),ROUND(F29/C29,0),"") | H29: Свободно
A30: № 29 | B30: А-ФРЕЙМ | C30: 40 | G30: =IF(AND(F30>0,C30>0),ROUND(F30/C30,0),"") | H30: Продано
A31: № 30 | B31: А-ФРЕЙМ | C31: 40 | F31: 11500000 | G31: =IF(AND(F31>0,C31>0),ROUND(F31/C31,0),"") | H31: Свободно (акция)
A32: № 31 | B32: А-ФРЕЙМ | C32: 40 | F32: 12000000 | G32: =IF(AND(F32>0,C32>0),ROUND(F32/C32,0),"") | H32: Свободно
A33: № 32 | B33: А-ФРЕЙМ | C33: 40 | F33: 12000000 | G33: =IF(AND(F33>0,C33>0),ROUND(F33/C33,0),"") | H33: Свободно
A34: № 33 | B34: А-ФРЕЙМ | C34: 40 | G34: =IF(AND(F34>0,C34>0),ROUND(F34/C34,0),"") | H34: Продано
A35: № 34 | B35: А-ФРЕЙМ | C35: 40 | F35: 12000000 | G35: =IF(AND(F35>0,C35>0),ROUND(F35/C35,0),"") | H35: Свободно
A36: № 35 | B36: А-ФРЕЙМ | C36: 40 | F36: 12000000 | G36: =IF(AND(F36>0,C36>0),ROUND(F36/C36,0),"") | H36: Свободно
A37: № 36 | B37: А-ФРЕЙМ | C37: 40 | F37: 12000000 | G37: =IF(AND(F37>0,C37>0),ROUND(F37/C37,0),"") | H37: Свободно
A38: № 37 | B38: БАРНХАУС | C38: 62 | G38: =IF(AND(F38>0,C38>0),ROUND(F38/C38,0),"") | H38: Резерв

Sheet Как пользоваться
A1: СЛУЖЕБНЫЙ ЛИСТ — скрыт. Работникам: «Шахматка участки» + «Карта».
A2: Данные и формулы — на скрытых листах «Данные участки», «Каталог», «Прайс».
A3: Цена земли = площадь × ₽/м². Если выбран проект (кол. G) — ставка от этого дома.
A4: Угловая надбавка к дому: площадь × 1 000 ₽ (отдельно от земли).
A5: После ввода цен — напишите, обновлю примечания на шахматке.

Sheet Шахматка SPACE
B2: Château Del Mare
C12: АКЦИЯ | F12: ПРОДАНО | I12: ЗАБРОНИРОВАНО
B14: № 1 | C14: БАРНХАУС | E14: № 2 | F14: А-ФРЕЙМ | H14: № 3 | I14: А-ФРЕЙМ | K14: № 4 | L14: А-ФРЕЙМ | N14: № 5 | O14: А-ФРЕЙМ | Q14: № 6 | R14: БАРНХАУС | T14: № 7 | U14: А-ФРЕЙМ
B15: ЦЕНА: | C15: ПРОДАНО | E15: ЦЕНА: | F15: ПРОДАНО | H15: ЦЕНА: | I15: ПРОДАНО | K15: ЦЕНА: | L15: 14500000 | N15: ЦЕНА: | O15: ПРОДАНО | Q15: ЦЕНА: | R15: ПРОДАНО | T15: ЦЕНА: | U15: 12000000
B16: ПЛОЩАДЬ: | C16: 62 | E16: ПЛОЩАДЬ: | F16: 40 | H16: ПЛОЩАДЬ: | I16: 40 | K16: ПЛОЩАДЬ: | L16: 40 | N16: ПЛОЩАДЬ: | O16: 40 | Q16: ПЛОЩАДЬ: | R16: 62 | T16: ПЛОЩАДЬ: | U16: 40
B19: № 8 | C19: А-ФРЕЙМ | E19: № 9 | F19: А-ФРЕЙМ | H19: № 10 | I19: А-ФРЕЙМ | K19: № 11 | L19: БАРНХАУС | N19: № 12 | O19: А-ФРЕЙМ | Q19: № 13 | R19: А-ФРЕЙМ | T19: № 14 | U19: А-ФРЕЙМ
B20: ЦЕНА: | C20: 12000000 | E20: ЦЕНА: | F20: 12000000 | H20: ЦЕНА: | I20: 12000000 | K20: ЦЕНА: | L20: 16000000 | N20: ЦЕНА: | O20: ПРОДАНО | Q20: ЦЕНА: | R20: 12000000 | T20: ЦЕНА: | U20: 12000000
B21: ПЛОЩАДЬ: | C21: 40 | E21: ПЛОЩАДЬ: | F21: 40 | H21: ПЛОЩАДЬ: | I21: 40 | K21: ПЛОЩАДЬ: | L21: 62 | N21: ПЛОЩАДЬ: | O21: 62 | Q21: ПЛОЩАДЬ: | R21: 40 | T21: ПЛОЩАДЬ: | U21: 40
B24: № 15 | C24: А-ФРЕЙМ | E24: № 16 | F24: БАРНХАУС | H24: № 17 | I24: А-ФРЕЙМ | K24: № 18 | L24: А-ФРЕЙМ | N24: № 19 | O24: А-ФРЕЙМ | Q24: № 20 | R24: А-ФРЕЙМ | T24: № 21 | U24: БАРНХАУС
B25: ЦЕНА: | C25: 11500000 | E25: ЦЕНА: | F25: ПРОДАНО | H25: ЦЕНА: | I25: 12000000 | K25: ЦЕНА: | L25: 12000000 | N25: ЦЕНА: | O25: ПРОДАНО | Q25: ЦЕНА: | R25: ПРОДАНО | T25: ЦЕНА: | U25: ПРОДАНО
B26: ПЛОЩАДЬ: | C26: 40 | E26: ПЛОЩАДЬ: | F26: 40 | H26: ПЛОЩАДЬ: | I26: 40 | K26: ПЛОЩАДЬ: | L26: 62 | N26: ПЛОЩАДЬ: | O26: 40 | Q26: ПЛОЩАДЬ: | R26: 62 | T26: ПЛОЩАДЬ: | U26: 62
B29: № 22 | C29: А-ФРЕЙМ | E29: № 23 | F29: А-ФРЕЙМ | H29: № 24 | I29: А-ФРЕЙМ | K29: № 25 | L29: А-ФРЕЙМ | N29: № 26 | O29: А-ФРЕЙМ | Q29: № 27 | R29: БАРНХАУС | T29: № 28 | U29: А-ФРЕЙМ
B30: ЦЕНА: | C30: 12000000 | E30: ЦЕНА: | F30: 12000000 | H30: ЦЕНА: | I30: 12000000 | K30: ЦЕНА: | L30: 12000000 | N30: ЦЕНА: | O30: 12000000 | Q30: ЦЕНА: | R30: ПРОДАНО | T30: ЦЕНА: | U30: 12000000
B31: ПЛОЩАДЬ: | C31: 40 | E31: ПЛОЩАДЬ: | F31: 40 | H31: ПЛОЩАДЬ: | I31: 40 | K31: ПЛОЩАДЬ: | L31: 40 | N31: ПЛОЩАДЬ: | O31: 40 | Q31: ПЛОЩАДЬ: | R31: 62 | T31: ПЛОЩАДЬ: | U31: 40
B34: № 29 | C34: А-ФРЕЙМ | E34: № 30 | F34: А-ФРЕЙМ | H34: № 31 | I34: А-ФРЕЙМ | K34: № 32 | L34: А-ФРЕЙМ | N34: № 33 | O34: А-ФРЕЙМ | Q34: № 34 | R34: А-ФРЕЙМ | T34: № 35 | U34: А-ФРЕЙМ
B35: ЦЕНА: | C35: ПРОДАНО | E35: ЦЕНА: | F35: 11500000 | H35: ЦЕНА: | I35: 12000000 | K35: ЦЕНА: | L35: 12000000 | N35: ЦЕНА: | O35: ПРОДАНО | Q35: ЦЕНА: | R35: 12000000 | T35: ЦЕНА: | U35: 12000000
B36: ПЛОЩАДЬ: | C36: 40 | E36: ПЛОЩАДЬ: | F36: 40 | H36: ПЛОЩАДЬ: | I36: 40 | K36: ПЛОЩАДЬ: | L36: 40 | N36: ПЛОЩАДЬ: | O36: 40 | Q36: ПЛОЩАДЬ: | R36: 40 | T36: ПЛОЩАДЬ: | U36: 40
B39: № 36 | C39: А-ФРЕЙМ | E39: № 37 | F39: БАРНХАУС
B40: ЦЕНА: | C40: 12000000 | E40: ЦЕНА: | F40: РЕЗЕРВ
B41: ПЛОЩАДЬ: | C41: 40 | E41: ПЛОЩАДЬ: | F41: 62

Sheet Шахматка участков
A1: Château Del Mare
B10: Екатериниская | T10: Екатериниская | AL10: Екатериниская
B12: № 1 | C12: Коммерция | D12: № 2 | E12: Коммерция | F12: № 2 | G12: Коммерция | H12: № 2 | I12: Коммерция | J12: № 3 | K12: Коммерция | L12: № 3 | M12: Коммерция | N12: № 3 | O12: Коммерция | P12: № 4 | Q12: Коммерция | T12: № 2 | U12: Коммерция | V12: № 3 | W12: Коммерция | X12: № 3 | Y12: Коммерция | Z12: № 3 | AA12: Коммерция | AB12: № 4 | AC12: Коммерция | AD12: № 4 | AE12: Коммерция | AF12: № 4 | AG12: Коммерция | AH12: № 5 | AI12: Коммерция | AL12: № 3 | AM12: Коммерция | AN12: № 4 | AO12: Коммерция | AP12: № 4 | AQ12: Коммерция | AR12: № 4 | AS12: Коммерция | AT12: № 5 | AU12: Коммерция | AV12: № 5 | AW12: Коммерция | AX12: № 5 | AY12: Коммерция | AZ12: № 6 | BA12: Коммерция
B13: ЦЕНА: | C13: ПРОДАНО | D13: ЦЕНА: | E13: ПРОДАНО | F13: ЦЕНА: | G13: ПРОДАНО | H13: ЦЕНА: | I13: ПРОДАНО | J13: ЦЕНА: | K13: ПРОДАНО | L13: ЦЕНА: | M13: ПРОДАНО | N13: ЦЕНА: | O13: ПРОДАНО | P13: ЦЕНА: | Q13: ПРОДАНО | T13: ЦЕНА: | U13: ПРОДАНО | V13: ЦЕНА: | W13: ПРОДАНО | X13: ЦЕНА: | Y13: ПРОДАНО | Z13: ЦЕНА: | AA13: ПРОДАНО | AB13: ЦЕНА: | AC13: ПРОДАНО | AD13: ЦЕНА: | AE13: ПРОДАНО | AF13: ЦЕНА: | AG13: ПРОДАНО | AH13: ЦЕНА: | AI13: ПРОДАНО | AL13: ЦЕНА: | AM13: ПРОДАНО | AN13: ЦЕНА: | AO13: ПРОДАНО | AP13: ЦЕНА: | AQ13: ПРОДАНО | AR13: ЦЕНА: | AS13: ПРОДАНО | AT13: ЦЕНА: | AU13: ПРОДАНО | AV13: ЦЕНА: | AW13: ПРОДАНО | AX13: ЦЕНА: | AY13: ПРОДАНО | AZ13: ЦЕНА: | BA13: ПРОДАНО
B14: ПЛОЩАДЬ: | C14: 62 | D14: ПЛОЩАДЬ: | E14: 63 | F14: ПЛОЩАДЬ: | G14: 63 | H14: ПЛОЩАДЬ: | I14: 63 | J14: ПЛОЩАДЬ: | K14: 64 | L14: ПЛОЩАДЬ: | M14: 64 | N14: ПЛОЩАДЬ: | O14: 64 | P14: ПЛОЩАДЬ: | Q14: 65 | T14: ПЛОЩАДЬ: | U14: 63 | V14: ПЛОЩАДЬ: | W14: 64 | X14: ПЛОЩАДЬ: | Y14: 64 | Z14: ПЛОЩАДЬ: | AA14: 64 | AB14: ПЛОЩАДЬ: | AC14: 65 | AD14: ПЛОЩАДЬ: | AE14: 65 | AF14: ПЛОЩАДЬ: | AG14: 65 | AH14: ПЛОЩАДЬ: | AI14: 66 | AL14: ПЛОЩАДЬ: | AM14: 64 | AN14: ПЛОЩАДЬ: | AO14: 65 | AP14: ПЛОЩАДЬ: | AQ14: 65 | AR14: ПЛОЩАДЬ: | AS14: 65 | AT14: ПЛОЩАДЬ: | AU14: 66 | AV14: ПЛОЩАДЬ: | AW14: 66 | AX14: ПЛОЩАДЬ: | AY14: 66 | AZ14: ПЛОЩАДЬ: | BA14: 67
B15: № 2 | C15: Коммерция | D15: № 3 | E15: Коммерция | F15: № 3 | G15: Коммерция | H15: № 3 | I15: Коммерция | J15: № 4 | K15: Коммерция | L15: № 4 | M15: Коммерция | N15: № 4 | O15: Коммерция | P15: № 5 | Q15: Коммерция | T15: № 3 | U15: Коммерция | V15: № 4 | W15: Коммерция | X15: № 4 | Y15: Коммерция | Z15: № 4 | AA15: Коммерция | AB15: № 5 | AC15: Коммерция | AD15: № 5 | AE15: Коммерция | AF15: № 5 | AG15: Коммерция | AH15: № 6 | AI15: Коммерция | AL15: № 4 | AM15: Коммерция | AN15: № 5 | AO15: Коммерция | AP15: № 5 | AQ15: Коммерция | AR15: № 5 | AS15: Коммерция | AT15: № 6 | AU15: Коммерция | AV15: № 6 | AW15: Коммерция | AX15: № 6 | AY15: Коммерция | AZ15: № 7 | BA15: Коммерция
B16: ЦЕНА: | C16: ПРОДАНО | D16: ЦЕНА: | E16: ПРОДАНО | F16: ЦЕНА: | G16: ПРОДАНО | H16: ЦЕНА: | I16: ПРОДАНО | J16: ЦЕНА: | K16: ПРОДАНО | L16: ЦЕНА: | M16: ПРОДАНО | N16: ЦЕНА: | O16: ПРОДАНО | P16: ЦЕНА: | Q16: ПРОДАНО | T16: ЦЕНА: | U16: ПРОДАНО | V16: ЦЕНА: | W16: ПРОДАНО | X16: ЦЕНА: | Y16: ПРОДАНО | Z16: ЦЕНА: | AA16: ПРОДАНО | AB16: ЦЕНА: | AC16: ПРОДАНО | AD16: ЦЕНА: | AE16: ПРОДАНО | AF16: ЦЕНА: | AG16: ПРОДАНО | AH16: ЦЕНА: | AI16: ПРОДАНО | AL16: ЦЕНА: | AM16: ПРОДАНО | AN16: ЦЕНА: | AO16: ПРОДАНО | AP16: ЦЕНА: | AQ16: ПРОДАНО | AR16: ЦЕНА: | AS16: ПРОДАНО | AT16: ЦЕНА: | AU16: ПРОДАНО | AV16: ЦЕНА: | AW16: ПРОДАНО | AX16: ЦЕНА: | AY16: ПРОДАНО | AZ16: ЦЕНА: | BA16: ПРОДАНО
B17: ПЛОЩАДЬ: | C17: 63 | D17: ПЛОЩАДЬ: | E17: 64 | F17: ПЛОЩАДЬ: | G17: 64 | H17: ПЛОЩАДЬ: | I17: 64 | J17: ПЛОЩАДЬ: | K17: 65 | L17: ПЛОЩАДЬ: | M17: 65 | N17: ПЛОЩАДЬ: | O17: 65 | P17: ПЛОЩАДЬ: | Q17: 66 | T17: ПЛОЩАДЬ: | U17: 64 | V17: ПЛОЩАДЬ: | W17: 65 | X17: ПЛОЩАДЬ: | Y17: 65 | Z17: ПЛОЩАДЬ: | AA17: 65 | AB17: ПЛОЩАДЬ: | AC17: 66 | AD17: ПЛОЩАДЬ: | AE17: 66 | AF17: ПЛОЩАДЬ: | AG17: 66 | AH17: ПЛОЩАДЬ: | AI17: 67 | AL17: ПЛОЩАДЬ: | AM17: 65 | AN17: ПЛОЩАДЬ: | AO17: 66 | AP17: ПЛОЩАДЬ: | AQ17: 66 | AR17: ПЛОЩАДЬ: | AS17: 66 | AT17: ПЛОЩАДЬ: | AU17: 67 | AV17: ПЛОЩАДЬ: | AW17: 67 | AX17: ПЛОЩАДЬ: | AY17: 67 | AZ17: ПЛОЩАДЬ: | BA17: 68
B18: Цветочная | T18: Цветочная | AL18: Цветочная
B20: № 2 | C20: Коммерция | D20: № 3 | E20: Коммерция | F20: № 3 | G20: Коммерция | H20: № 3 | I20: Коммерция | J20: № 4 | K20: Коммерция | L20: № 4 | M20: Коммерция | N20: № 4 | O20: Коммерция | P20: № 5 | Q20: Коммерция | T20: № 3 | U20: Коммерция | V20: № 4 | W20: Коммерция | X20: № 4 | Y20: Коммерция | Z20: № 4 | AA20: Коммерция | AB20: № 5 | AC20: Коммерция | AD20: № 5 | AE20: Коммерция | AF20: № 5 | AG20: Коммерция | AH20: № 6 | AI20: Коммерция | AL20: № 4 | AM20: Коммерция | AN20: № 5 | AO20: Коммерция | AP20: № 5 | AQ20: Коммерция | AR20: № 5 | AS20: Коммерция | AT20: № 6 | AU20: Коммерция | AV20: № 6 | AW20: Коммерция | AX20: № 6 | AY20: Коммерция | AZ20: № 7 | BA20: Коммерция
B21: ЦЕНА: | C21: ПРОДАНО | D21: ЦЕНА: | E21: ПРОДАНО | F21: ЦЕНА: | G21: ПРОДАНО | H21: ЦЕНА: | I21: ПРОДАНО | J21: ЦЕНА: | K21: ПРОДАНО | L21: ЦЕНА: | M21: ПРОДАНО | N21: ЦЕНА: | O21: ПРОДАНО | P21: ЦЕНА: | Q21: ПРОДАНО | T21: ЦЕНА: | U21: ПРОДАНО | V21: ЦЕНА: | W21: ПРОДАНО | X21: ЦЕНА: | Y21: ПРОДАНО | Z21: ЦЕНА: | AA21: ПРОДАНО | AB21: ЦЕНА: | AC21: ПРОДАНО | AD21: ЦЕНА: | AE21: ПРОДАНО | AF21: ЦЕНА: | AG21: ПРОДАНО | AH21: ЦЕНА: | AI21: ПРОДАНО | AL21: ЦЕНА: | AM21: ПРОДАНО | AN21: ЦЕНА: | AO21: ПРОДАНО | AP21: ЦЕНА: | AQ21: ПРОДАНО | AR21: ЦЕНА: | AS21: ПРОДАНО | AT21: ЦЕНА: | AU21: ПРОДАНО | AV21: ЦЕНА: | AW21: ПРОДАНО | AX21: ЦЕНА: | AY21: ПРОДАНО | AZ21: ЦЕНА: | BA21: ПРОДАНО
B22: ПЛОЩАДЬ: | C22: 63 | D22: ПЛОЩАДЬ: | E22: 64 | F22: ПЛОЩАДЬ: | G22: 64 | H22: ПЛОЩАДЬ: | I22: 64 | J22: ПЛОЩАДЬ: | K22: 65 | L22: ПЛОЩАДЬ: | M22: 65 | N22: ПЛОЩАДЬ: | O22: 65 | P22: ПЛОЩАДЬ: | Q22: 66 | T22: ПЛОЩАДЬ: | U22: 64 | V22: ПЛОЩАДЬ: | W22: 65 | X22: ПЛОЩАДЬ: | Y22: 65 | Z22: ПЛОЩАДЬ: | AA22: 65 | AB22: ПЛОЩАДЬ: | AC22: 66 | AD22: ПЛОЩАДЬ: | AE22: 66 | AF22: ПЛОЩАДЬ: | AG22: 66 | AH22: ПЛОЩАДЬ: | AI22: 67 | AL22: ПЛОЩАДЬ: | AM22: 65 | AN22: ПЛОЩАДЬ: | AO22: 66 | AP22: ПЛОЩАДЬ: | AQ22: 66 | AR22: ПЛОЩАДЬ: | AS22: 66 | AT22: ПЛОЩАДЬ: | AU22: 67 | AV22: ПЛОЩАДЬ: | AW22: 67 | AX22: ПЛОЩАДЬ: | AY22: 67 | AZ22: ПЛОЩАДЬ: | BA22: 68
B23: № 3 | C23: Коммерция | D23: № 4 | E23: Коммерция | F23: № 4 | G23: Коммерция | H23: № 4 | I23: Коммерция | J23: № 5 | K23: Коммерция | L23: № 5 | M23: Коммерция | N23: № 5 | O23: Коммерция | P23: № 6 | Q23: Коммерция | T23: № 4 | U23: Коммерция | V23: № 5 | W23: Коммерция | X23: № 5 | Y23: Коммерция | Z23: № 5 | AA23: Коммерция | AB23: № 6 | AC23: Коммерция | AD23: № 6 | AE23: Коммерция | AF23: № 6 | AG23: Коммерция | AH23: № 7 | AI23: Коммерция | AL23: № 5 | AM23: Коммерция | AN23: № 6 | AO23: Коммерция | AP23: № 6 | AQ23: Коммерция | AR23: № 6 | AS23: Коммерция | AT23: № 7 | AU23: Коммерция | AV23: № 7 | AW23: Коммерция | AX23: № 7 | AY23: Коммерция | AZ23: № 8 | BA23: Коммерция
B24: ЦЕНА: | C24: ПРОДАНО | D24: ЦЕНА: | E24: ПРОДАНО | F24: ЦЕНА: | G24: ПРОДАНО | H24: ЦЕНА: | I24: ПРОДАНО | J24: ЦЕНА: | K24: ПРОДАНО | L24: ЦЕНА: | M24: ПРОДАНО | N24: ЦЕНА: | O24: ПРОДАНО | P24: ЦЕНА: | Q24: ПРОДАНО | T24: ЦЕНА: | U24: ПРОДАНО | V24: ЦЕНА: | W24: ПРОДАНО | X24: ЦЕНА: | Y24: ПРОДАНО | Z24: ЦЕНА: | AA24: ПРОДАНО | AB24: ЦЕНА: | AC24: ПРОДАНО | AD24: ЦЕНА: | AE24: ПРОДАНО | AF24: ЦЕНА: | AG24: ПРОДАНО | AH24: ЦЕНА: | AI24: ПРОДАНО | AL24: ЦЕНА: | AM24: ПРОДАНО | AN24: ЦЕНА: | AO24: ПРОДАНО | AP24: ЦЕНА: | AQ24: ПРОДАНО | AR24: ЦЕНА: | AS24: ПРОДАНО | AT24: ЦЕНА: | AU24: ПРОДАНО | AV24: ЦЕНА: | AW24: ПРОДАНО | AX24: ЦЕНА: | AY24: ПРОДАНО | AZ24: ЦЕНА: | BA24: ПРОДАНО
B25: ПЛОЩАДЬ: | C25: 64 | D25: ПЛОЩАДЬ: | E25: 65 | F25: ПЛОЩАДЬ: | G25: 65 | H25: ПЛОЩАДЬ: | I25: 65 | J25: ПЛОЩАДЬ: | K25: 66 | L25: ПЛОЩАДЬ: | M25: 66 | N25: ПЛОЩАДЬ: | O25: 66 | P25: ПЛОЩАДЬ: | Q25: 67 | T25: ПЛОЩАДЬ: | U25: 65 | V25: ПЛОЩАДЬ: | W25: 66 | X25: ПЛОЩАДЬ: | Y25: 66 | Z25: ПЛОЩАДЬ: | AA25: 66 | AB25: ПЛОЩАДЬ: | AC25: 67 | AD25: ПЛОЩАДЬ: | AE25: 67 | AF25: ПЛОЩАДЬ: | AG25: 67 | AH25: ПЛОЩАДЬ: | AI25: 68 | AL25: ПЛОЩАДЬ: | AM25: 66 | AN25: ПЛОЩАДЬ: | AO25: 67 | AP25: ПЛОЩАДЬ: | AQ25: 67 | AR25: ПЛОЩАДЬ: | AS25: 67 | AT25: ПЛОЩАДЬ: | AU25: 68 | AV25: ПЛОЩАДЬ: | AW25: 68 | AX25: ПЛОЩАДЬ: | AY25: 68 | AZ25: ПЛОЩАДЬ: | BA25: 69
B26: Корабельная | R26: Аллея с функциональными зонами и площадками | T26: Корабельная | AJ26: Аллея с функциональными зонами и площадками | AL26: Корабельная | BB26: Аллея с функциональными зонами и площадками
B28: № 3 | C28: Коммерция | D28: № 4 | E28: Коммерция | F28: № 4 | G28: Коммерция | H28: № 4 | I28: Коммерция | J28: № 5 | K28: Коммерция | L28: № 5 | M28: Коммерция | N28: № 5 | O28: Коммерция | P28: № 6 | Q28: Коммерция | T28: № 4 | U28: Коммерция | V28: № 5 | W28: Коммерция | X28: № 5 | Y28: Коммерция | Z28: № 5 | AA28: Коммерция | AB28: № 6 | AC28: Коммерция | AD28: № 6 | AE28: Коммерция | AF28: № 6 | AG28: Коммерция | AH28: № 7 | AI28: Коммерция | AL28: № 5 | AM28: Коммерция | AN28: № 6 | AO28: Коммерция | AP28: № 6 | AQ28: Коммерция | AR28: № 6 | AS28: Коммерция | AT28: № 7 | AU28: Коммерция | AV28: № 7 | AW28: Коммерция | AX28: № 7 | AY28: Коммерция | AZ28: № 8 | BA28: Коммерция
B29: ЦЕНА: | C29: ПРОДАНО | D29: ЦЕНА: | E29: ПРОДАНО | F29: ЦЕНА: | G29: ПРОДАНО | H29: ЦЕНА: | I29: ПРОДАНО | J29: ЦЕНА: | K29: ПРОДАНО | L29: ЦЕНА: | M29: ПРОДАНО | N29: ЦЕНА: | O29: ПРОДАНО | P29: ЦЕНА: | Q29: ПРОДАНО | T29: ЦЕНА: | U29: ПРОДАНО | V29: ЦЕНА: | W29: ПРОДАНО | X29: ЦЕНА: | Y29: ПРОДАНО | Z29: ЦЕНА: | AA29: ПРОДАНО | AB29: ЦЕНА: | AC29: ПРОДАНО | AD29: ЦЕНА: | AE29: ПРОДАНО | AF29: ЦЕНА: | AG29: ПРОДАНО | AH29: ЦЕНА: | AI29: ПРОДАНО | AL29: ЦЕНА: | AM29: ПРОДАНО | AN29: ЦЕНА: | AO29: ПРОДАНО | AP29: ЦЕНА: | AQ29: ПРОДАНО | AR29: ЦЕНА: | AS29: ПРОДАНО | AT29: ЦЕНА: | AU29: ПРОДАНО | AV29: ЦЕНА: | AW29: ПРОДАНО | AX29: ЦЕНА: | AY29: ПРОДАНО | AZ29: ЦЕНА: | BA29: ПРОДАНО
B30: ПЛОЩАДЬ: | C30: 64 | D30: ПЛОЩАДЬ: | E30: 65 | F30: ПЛОЩАДЬ: | G30: 65 | H30: ПЛОЩАДЬ: | I30: 65 | J30: ПЛОЩАДЬ: | K30: 66 | L30: ПЛОЩАДЬ: | M30: 66 | N30: ПЛОЩАДЬ: | O30: 66 | P30: ПЛОЩАДЬ: | Q30: 67 | T30: ПЛОЩАДЬ: | U30: 65 | V30: ПЛОЩАДЬ: | W30: 66 | X30: ПЛОЩАДЬ: | Y30: 66 | Z30: ПЛОЩАДЬ: | AA30: 66 | AB30: ПЛОЩАДЬ: | AC30: 67 | AD30: ПЛОЩАДЬ: | AE30: 67 | AF30: ПЛОЩАДЬ: | AG30: 67 | AH30: ПЛОЩАДЬ: | AI30: 68 | AL30: ПЛОЩАДЬ: | AM30: 66 | AN30: ПЛОЩАДЬ: | AO30: 67 | AP30: ПЛОЩАДЬ: | AQ30: 67 | AR30: ПЛОЩАДЬ: | AS30: 67 | AT30: ПЛОЩАДЬ: | AU30: 68 | AV30: ПЛОЩАДЬ: | AW30: 68 | AX30: ПЛОЩАДЬ: | AY30: 68 | AZ30: ПЛОЩАДЬ: | BA30: 69
B31: № 4 | C31: Коммерция | D31: № 5 | E31: Коммерция | F31: № 5 | G31: Коммерция | H31: № 5 | I31: Коммерция | J31: № 6 | K31: Коммерция | L31: № 6 | M31: Коммерция | N31: № 6 | O31: Коммерция | P31: № 7 | Q31: Коммерция | T31: № 5 | U31: Коммерция | V31: № 6 | W31: Коммерция | X31: № 6 | Y31: Коммерция | Z31: № 6 | AA31: Коммерция | AB31: № 7 | AC31: Коммерция | AD31: № 7 | AE31: Коммерция | AF31: № 7 | AG31: Коммерция | AH31: № 8 | AI31: Коммерция | AL31: № 6 | AM31: Коммерция | AN31: № 7 | AO31: Коммерция | AP31: № 7 | AQ31: Коммерция | AR31: № 7 | AS31: Коммерция | AT31: № 8 | AU31: Коммерция | AV31: № 8 | AW31: Коммерция | AX31: № 8 | AY31: Коммерция | AZ31: № 9 | BA31: Коммерция
B32: ЦЕНА: | C32: ПРОДАНО | D32: ЦЕНА: | E32: ПРОДАНО | F32: ЦЕНА: | G32: ПРОДАНО | H32: ЦЕНА: | I32: ПРОДАНО | J32: ЦЕНА: | K32: ПРОДАНО | L32: ЦЕНА: | M32: ПРОДАНО | N32: ЦЕНА: | O32: ПРОДАНО | P32: ЦЕНА: | Q32: ПРОДАНО | T32: ЦЕНА: | U32: ПРОДАНО | V32: ЦЕНА: | W32: ПРОДАНО | X32: ЦЕНА: | Y32: ПРОДАНО | Z32: ЦЕНА: | AA32: ПРОДАНО | AB32: ЦЕНА: | AC32: ПРОДАНО | AD32: ЦЕНА: | AE32: ПРОДАНО | AF32: ЦЕНА: | AG32: ПРОДАНО | AH32: ЦЕНА: | AI32: ПРОДАНО | AL32: ЦЕНА: | AM32: ПРОДАНО | AN32: ЦЕНА: | AO32: ПРОДАНО | AP32: ЦЕНА: | AQ32: ПРОДАНО | AR32: ЦЕНА: | AS32: ПРОДАНО | AT32: ЦЕНА: | AU32: ПРОДАНО | AV32: ЦЕНА: | AW32: ПРОДАНО | AX32: ЦЕНА: | AY32: ПРОДАНО | AZ32: ЦЕНА: | BA32: ПРОДАНО
B33: ПЛОЩАДЬ: | C33: 65 | D33: ПЛОЩАДЬ: | E33: 66 | F33: ПЛОЩАДЬ: | G33: 66 | H33: ПЛОЩАДЬ: | I33: 66 | J33: ПЛОЩАДЬ: | K33: 67 | L33: ПЛОЩАДЬ: | M33: 67 | N33: ПЛОЩАДЬ: | O33: 67 | P33: ПЛОЩАДЬ: | Q33: 68 | T33: ПЛОЩАДЬ: | U33: 66 | V33: ПЛОЩАДЬ: | W33: 67 | X33: ПЛОЩАДЬ: | Y33: 67 | Z33: ПЛОЩАДЬ: | AA33: 67 | AB33: ПЛОЩАДЬ: | AC33: 68 | AD33: ПЛОЩАДЬ: | AE33: 68 | AF33: ПЛОЩАДЬ: | AG33: 68 | AH33: ПЛОЩАДЬ: | AI33: 69 | AL33: ПЛОЩАДЬ: | AM33: 67 | AN33: ПЛОЩАДЬ: | AO33: 68 | AP33: ПЛОЩАДЬ: | AQ33: 68 | AR33: ПЛОЩАДЬ: | AS33: 68 | AT33: ПЛОЩАДЬ: | AU33: 69 | AV33: ПЛОЩАДЬ: | AW33: 69 | AX33: ПЛОЩАДЬ: | AY33: 69 | AZ33: ПЛОЩАДЬ: | BA33: 70
B34: Айвазовского | T34: Айвазовского | AL34: Айвазовского
B36: № 2 | C36: Коммерция | D36: № 3 | E36: Коммерция | F36: № 3 | G36: Коммерция | H36: № 3 | I36: Коммерция | J36: № 4 | K36: Коммерция | L36: № 4 | M36: Коммерция | N36: № 4 | O36: Коммерция | P36: № 5 | Q36: Коммерция | T36: № 3 | U36: Коммерция | V36: № 4 | W36: Коммерция | X36: № 4 | Y36: Коммерция | Z36: № 4 | AA36: Коммерция | AB36: № 5 | AC36: Коммерция | AD36: № 5 | AE36: Коммерция | AF36: № 5 | AG36: Коммерция | AH36: № 6 | AI36: Коммерция | AL36: № 4 | AM36: Коммерция | AN36: № 5 | AO36: Коммерция | AP36: № 5 | AQ36: Коммерция | AR36: № 5 | AS36: Коммерция | AT36: № 6 | AU36: Коммерция | AV36: № 6 | AW36: Коммерция | AX36: № 6 | AY36: Коммерция | AZ36: № 7 | BA36: Коммерция
B37: ЦЕНА: | C37: ПРОДАНО | D37: ЦЕНА: | E37: ПРОДАНО | F37: ЦЕНА: | G37: ПРОДАНО | H37: ЦЕНА: | I37: ПРОДАНО | J37: ЦЕНА: | K37: ПРОДАНО | L37: ЦЕНА: | M37: ПРОДАНО | N37: ЦЕНА: | O37: ПРОДАНО | P37: ЦЕНА: | Q37: ПРОДАНО | T37: ЦЕНА: | U37: ПРОДАНО | V37: ЦЕНА: | W37: ПРОДАНО | X37: ЦЕНА: | Y37: ПРОДАНО | Z37: ЦЕНА: | AA37: ПРОДАНО | AB37: ЦЕНА: | AC37: ПРОДАНО | AD37: ЦЕНА: | AE37: ПРОДАНО | AF37: ЦЕНА: | AG37: ПРОДАНО | AH37: ЦЕНА: | AI37: ПРОДАНО | AL37: ЦЕНА: | AM37: ПРОДАНО | AN37: ЦЕНА: | AO37: ПРОДАНО | AP37: ЦЕНА: | AQ37: ПРОДАНО | AR37: ЦЕНА: | AS37: ПРОДАНО | AT37: ЦЕНА: | AU37: ПРОДАНО | AV37: ЦЕНА: | AW37: ПРОДАНО | AX37: ЦЕНА: | AY37: ПРОДАНО | AZ37: ЦЕНА: | BA37: ПРОДАНО
B38: ПЛОЩАДЬ: | C38: 63 | D38: ПЛОЩАДЬ: | E38: 64 | F38: ПЛОЩАДЬ: | G38: 64 | H38: ПЛОЩАДЬ: | I38: 64 | J38: ПЛОЩАДЬ: | K38: 65 | L38: ПЛОЩАДЬ: | M38: 65 | N38: ПЛОЩАДЬ: | O38: 65 | P38: ПЛОЩАДЬ: | Q38: 66 | T38: ПЛОЩАДЬ: | U38: 64 | V38: ПЛОЩАДЬ: | W38: 65 | X38: ПЛОЩАДЬ: | Y38: 65 | Z38: ПЛОЩАДЬ: | AA38: 65 | AB38: ПЛОЩАДЬ: | AC38: 66 | AD38: ПЛОЩАДЬ: | AE38: 66 | AF38: ПЛОЩАДЬ: | AG38: 66 | AH38: ПЛОЩАДЬ: | AI38: 67 | AL38: ПЛОЩАДЬ: | AM38: 65 | AN38: ПЛОЩАДЬ: | AO38: 66 | AP38: ПЛОЩАДЬ: | AQ38: 66 | AR38: ПЛОЩАДЬ: | AS38: 66 | AT38: ПЛОЩАДЬ: | AU38: 67 | AV38: ПЛОЩАДЬ: | AW38: 67 | AX38: ПЛОЩАДЬ: | AY38: 67 | AZ38: ПЛОЩАДЬ: | BA38: 68
B39: № 3 | C39: Коммерция | D39: № 4 | E39: Коммерция | F39: № 4 | G39: Коммерция | H39: № 4 | I39: Коммерция | J39: № 5 | K39: Коммерция | L39: № 5 | M39: Коммерция | N39: № 5 | O39: Коммерция | P39: № 6 | Q39: Коммерция | T39: № 4 | U39: Коммерция | V39: № 5 | W39: Коммерция | X39: № 5 | Y39: Коммерция | Z39: № 5 | AA39: Коммерция | AB39: № 6 | AC39: Коммерция | AD39: № 6 | AE39: Коммерция | AF39: № 6 | AG39: Коммерция | AH39: № 7 | AI39: Коммерция | AL39: № 5 | AM39: Коммерция | AN39: № 6 | AO39: Коммерция | AP39: № 6 | AQ39: Коммерция | AR39: № 6 | AS39: Коммерция | AT39: № 7 | AU39: Коммерция | AV39: № 7 | AW39: Коммерция | AX39: № 7 | AY39: Коммерция | AZ39: № 8 | BA39: Коммерция
B40: ЦЕНА: | C40: ПРОДАНО | D40: ЦЕНА: | E40: ПРОДАНО | F40: ЦЕНА: | G40: ПРОДАНО | H40: ЦЕНА: | I40: ПРОДАНО | J40: ЦЕНА: | K40: ПРОДАНО | L40: ЦЕНА: | M40: ПРОДАНО | N40: ЦЕНА: | O40: ПРОДАНО | P40: ЦЕНА: | Q40: ПРОДАНО | T40: ЦЕНА: | U40: ПРОДАНО | V40: ЦЕНА: | W40: ПРОДАНО | X40: ЦЕНА: | Y40: ПРОДАНО | Z40: ЦЕНА: | AA40: ПРОДАНО | AB40: ЦЕНА: | AC40: ПРОДАНО | AD40: ЦЕНА: | AE40: ПРОДАНО | AF40: ЦЕНА: | AG40: ПРОДАНО | AH40: ЦЕНА: | AI40: ПРОДАНО | AL40: ЦЕНА: | AM40: ПРОДАНО | AN40: ЦЕНА: | AO40: ПРОДАНО | AP40: ЦЕНА: | AQ40: ПРОДАНО | AR40: ЦЕНА: | AS40: ПРОДАНО | AT40: ЦЕНА: | AU40: ПРОДАНО | AV40: ЦЕНА: | AW40: ПРОДАНО | AX40: ЦЕНА: | AY40: ПРОДАНО | AZ40: ЦЕНА: | BA40: ПРОДАНО
B41: ПЛОЩАДЬ: | C41: 64 | D41: ПЛОЩАДЬ: | E41: 65 | F41: ПЛОЩАДЬ: | G41: 65 | H41: ПЛОЩАДЬ: | I41: 65 | J41: ПЛОЩАДЬ: | K41: 66 | L41: ПЛОЩАДЬ: | M41: 66 | N41: ПЛОЩАДЬ: | O41: 66 | P41: ПЛОЩАДЬ: | Q41: 67 | T41: ПЛОЩАДЬ: | U41: 65 | V41: ПЛОЩАДЬ: | W41: 66 | X41: ПЛОЩАДЬ: | Y41: 66 | Z41: ПЛОЩАДЬ: | AA41: 66 | AB41: ПЛОЩАДЬ: | AC41: 67 | AD41: ПЛОЩАДЬ: | AE41: 67 | AF41: ПЛОЩАДЬ: | AG41: 67 | AH41: ПЛОЩАДЬ: | AI41: 68 | AL41: ПЛОЩАДЬ: | AM41: 66 | AN41: ПЛОЩАДЬ: | AO41: 67 | AP41: ПЛОЩАДЬ: | AQ41: 67 | AR41: ПЛОЩАДЬ: | AS41: 67 | AT41: ПЛОЩАДЬ: | AU41: 68 | AV41: ПЛОЩАДЬ: | AW41: 68 | AX41: ПЛОЩАДЬ: | AY41: 68 | AZ41: ПЛОЩАДЬ: | BA41: 69
B42: Луначарского | T42: Луначарского | AL42: Луначарского
B44: № 3 | C44: Коммерция | D44: № 4 | E44: Коммерция | F44: № 4 | G44: Коммерция | H44: № 4 | I44: Коммерция | J44: № 5 | K44: Коммерция | L44: № 5 | M44: Коммерция | N44: № 5 | O44: Коммерция | P44: № 6 | Q44: Коммерция | T44: № 4 | U44: Коммерция | V44: № 5 | W44: Коммерция | X44: № 5 | Y44: Коммерция | Z44: № 5 | AA44: Коммерция | AB44: № 6 | AC44: Коммерция | AD44: № 6 | AE44: Коммерция | AF44: № 6 | AG44: Коммерция | AH44: № 7 | AI44: Коммерция | AL44: № 5 | AM44: Коммерция | AN44: № 6 | AO44: Коммерция | AP44: № 6 | AQ44: Коммерция | AR44: № 6 | AS44: Коммерция | AT44: № 7 | AU44: Коммерция | AV44: № 7 | AW44: Коммерция | AX44: № 7 | AY44: Коммерция | AZ44: № 8 | BA44: Коммерция
B45: ЦЕНА: | C45: ПРОДАНО | D45: ЦЕНА: | E45: ПРОДАНО | F45: ЦЕНА: | G45: ПРОДАНО | H45: ЦЕНА: | I45: ПРОДАНО | J45: ЦЕНА: | K45: ПРОДАНО | L45: ЦЕНА: | M45: ПРОДАНО | N45: ЦЕНА: | O45: ПРОДАНО | P45: ЦЕНА: | Q45: ПРОДАНО | T45: ЦЕНА: | U45: ПРОДАНО | V45: ЦЕНА: | W45: ПРОДАНО | X45: ЦЕНА: | Y45: ПРОДАНО | Z45: ЦЕНА: | AA45: ПРОДАНО | AB45: ЦЕНА: | AC45: ПРОДАНО | AD45: ЦЕНА: | AE45: ПРОДАНО | AF45: ЦЕНА: | AG45: ПРОДАНО | AH45: ЦЕНА: | AI45: ПРОДАНО | AL45: ЦЕНА: | AM45: ПРОДАНО | AN45: ЦЕНА: | AO45: ПРОДАНО | AP45: ЦЕНА: | AQ45: ПРОДАНО | AR45: ЦЕНА: | AS45: ПРОДАНО | AT45: ЦЕНА: | AU45: ПРОДАНО | AV45: ЦЕНА: | AW45: ПРОДАНО | AX45: ЦЕНА: | AY45: ПРОДАНО | AZ45: ЦЕНА: | BA45: ПРОДАНО
B46: ПЛОЩАДЬ: | C46: 64 | D46: ПЛОЩАДЬ: | E46: 65 | F46: ПЛОЩАДЬ: | G46: 65 | H46: ПЛОЩАДЬ: | I46: 65 | J46: ПЛОЩАДЬ: | K46: 66 | L46: ПЛОЩАДЬ: | M46: 66 | N46: ПЛОЩАДЬ: | O46: 66 | P46: ПЛОЩАДЬ: | Q46: 67 | T46: ПЛОЩАДЬ: | U46: 65 | V46: ПЛОЩАДЬ: | W46: 66 | X46: ПЛОЩАДЬ: | Y46: 66 | Z46: ПЛОЩАДЬ: | AA46: 66 | AB46: ПЛОЩАДЬ: | AC46: 67 | AD46: ПЛОЩАДЬ: | AE46: 67 | AF46: ПЛОЩАДЬ: | AG46: 67 | AH46: ПЛОЩАДЬ: | AI46: 68 | AL46: ПЛОЩАДЬ: | AM46: 66 | AN46: ПЛОЩАДЬ: | AO46: 67 | AP46: ПЛОЩАДЬ: | AQ46: 67 | AR46: ПЛОЩАДЬ: | AS46: 67 | AT46: ПЛОЩАДЬ: | AU46: 68 | AV46: ПЛОЩАДЬ: | AW46: 68 | AX46: ПЛОЩАДЬ: | AY46: 68 | AZ46: ПЛОЩАДЬ: | BA46: 69
B47: № 4 | C47: Коммерция | D47: № 5 | E47: Коммерция | F47: № 5 | G47: Коммерция | H47: № 5 | I47: Коммерция | J47: № 6 | K47: Коммерция | L47: № 6 | M47: Коммерция | N47: № 6 | O47: Коммерция | P47: № 7 | Q47: Коммерция | T47: № 5 | U47: Коммерция | V47: № 6 | W47: Коммерция | X47: № 6 | Y47: Коммерция | Z47: № 6 | AA47: Коммерция | AB47: № 7 | AC47: Коммерция | AD47: № 7 | AE47: Коммерция | AF47: № 7 | AG47: Коммерция | AH47: № 8 | AI47: Коммерция | AL47: № 6 | AM47: Коммерция | AN47: № 7 | AO47: Коммерция | AP47: № 7 | AQ47: Коммерция | AR47: № 7 | AS47: Коммерция | AT47: № 8 | AU47: Коммерция | AV47: № 8 | AW47: Коммерция | AX47: № 8 | AY47: Коммерция | AZ47: № 9 | BA47: Коммерция
B48: ЦЕНА: | C48: ПРОДАНО | D48: ЦЕНА: | E48: ПРОДАНО | F48: ЦЕНА: | G48: ПРОДАНО | H48: ЦЕНА: | I48: ПРОДАНО | J48: ЦЕНА: | K48: ПРОДАНО | L48: ЦЕНА: | M48: ПРОДАНО | N48: ЦЕНА: | O48: ПРОДАНО | P48: ЦЕНА: | Q48: ПРОДАНО | T48: ЦЕНА: | U48: ПРОДАНО | V48: ЦЕНА: | W48: ПРОДАНО | X48: ЦЕНА: | Y48: ПРОДАНО | Z48: ЦЕНА: | AA48: ПРОДАНО | AB48: ЦЕНА: | AC48: ПРОДАНО | AD48: ЦЕНА: | AE48: ПРОДАНО | AF48: ЦЕНА: | AG48: ПРОДАНО | AH48: ЦЕНА: | AI48: ПРОДАНО | AL48: ЦЕНА: | AM48: ПРОДАНО | AN48: ЦЕНА: | AO48: ПРОДАНО | AP48: ЦЕНА: | AQ48: ПРОДАНО | AR48: ЦЕНА: | AS48: ПРОДАНО | AT48: ЦЕНА: | AU48: ПРОДАНО | AV48: ЦЕНА: | AW48: ПРОДАНО | AX48: ЦЕНА: | AY48: ПРОДАНО | AZ48: ЦЕНА: | BA48: ПРОДАНО
B49: ПЛОЩАДЬ: | C49: 65 | D49: ПЛОЩАДЬ: | E49: 66 | F49: ПЛОЩАДЬ: | G49: 66 | H49: ПЛОЩАДЬ: | I49: 66 | J49: ПЛОЩАДЬ: | K49: 67 | L49: ПЛОЩАДЬ: | M49: 67 | N49: ПЛОЩАДЬ: | O49: 67 | P49: ПЛОЩАДЬ: | Q49: 68 | T49: ПЛОЩАДЬ: | U49: 66 | V49: ПЛОЩАДЬ: | W49: 67 | X49: ПЛОЩАДЬ: | Y49: 67 | Z49: ПЛОЩАДЬ: | AA49: 67 | AB49: ПЛОЩАДЬ: | AC49: 68 | AD49: ПЛОЩАДЬ: | AE49: 68 | AF49: ПЛОЩАДЬ: | AG49: 68 | AH49: ПЛОЩАДЬ: | AI49: 69 | AL49: ПЛОЩАДЬ: | AM49: 67 | AN49: ПЛОЩАДЬ: | AO49: 68 | AP49: ПЛОЩАДЬ: | AQ49: 68 | AR49: ПЛОЩАДЬ: | AS49: 68 | AT49: ПЛОЩАДЬ: | AU49: 69 | AV49: ПЛОЩАДЬ: | AW49: 69 | AX49: ПЛОЩАДЬ: | AY49: 69 | AZ49: ПЛОЩАДЬ: | BA49: 70
B50: Дивноморская | T50: Дивноморская | AL50: Дивноморская
B52: № 4 | C52: Коммерция | D52: № 5 | E52: Коммерция | F52: № 5 | G52: Коммерция | H52: № 5 | I52: Коммерция | J52: № 6 | K52: Коммерция | L52: № 6 | M52: Коммерция | N52: № 6 | O52: Коммерция | P52: № 7 | Q52: Коммерция | T52: № 5 | U52: Коммерция | V52: № 6 | W52: Коммерция | X52: № 6 | Y52: Коммерция | Z52: № 6 | AA52: Коммерция | AB52: № 7 | AC52: Коммерция | AD52: № 7 | AE52: Коммерция | AF52: № 7 | AG52: Коммерция | AH52: № 8 | AI52: Коммерция | AL52: № 6 | AM52: Коммерция | AN52: № 7 | AO52: Коммерция | AP52: № 7 | AQ52: Коммерция | AR52: № 7 | AS52: Коммерция | AT52: № 8 | AU52: Коммерция | AV52: № 8 | AW52: Коммерция | AX52: № 8 | AY52: Коммерция | AZ52: № 9 | BA52: Коммерция
B53: ЦЕНА: | C53: ПРОДАНО | D53: ЦЕНА: | E53: ПРОДАНО | F53: ЦЕНА: | G53: ПРОДАНО | H53: ЦЕНА: | I53: ПРОДАНО | J53: ЦЕНА: | K53: ПРОДАНО | L53: ЦЕНА: | M53: ПРОДАНО | N53: ЦЕНА: | O53: ПРОДАНО | P53: ЦЕНА: | Q53: ПРОДАНО | T53: ЦЕНА: | U53: ПРОДАНО | V53: ЦЕНА: | W53: ПРОДАНО | X53: ЦЕНА: | Y53: ПРОДАНО | Z53: ЦЕНА: | AA53: ПРОДАНО | AB53: ЦЕНА: | AC53: ПРОДАНО | AD53: ЦЕНА: | AE53: ПРОДАНО | AF53: ЦЕНА: | AG53: ПРОДАНО | AH53: ЦЕНА: | AI53: ПРОДАНО | AL53: ЦЕНА: | AM53: ПРОДАНО | AN53: ЦЕНА: | AO53: ПРОДАНО | AP53: ЦЕНА: | AQ53: ПРОДАНО | AR53: ЦЕНА: | AS53: ПРОДАНО | AT53: ЦЕНА: | AU53: ПРОДАНО | AV53: ЦЕНА: | AW53: ПРОДАНО | AX53: ЦЕНА: | AY53: ПРОДАНО | AZ53: ЦЕНА: | BA53: ПРОДАНО
B54: ПЛОЩАДЬ: | C54: 65 | D54: ПЛОЩАДЬ: | E54: 66 | F54: ПЛОЩАДЬ: | G54: 66 | H54: ПЛОЩАДЬ: | I54: 66 | J54: ПЛОЩАДЬ: | K54: 67 | L54: ПЛОЩАДЬ: | M54: 67 | N54: ПЛОЩАДЬ: | O54: 67 | P54: ПЛОЩАДЬ: | Q54: 68 | T54: ПЛОЩАДЬ: | U54: 66 | V54: ПЛОЩАДЬ: | W54: 67 | X54: ПЛОЩАДЬ: | Y54: 67 | Z54: ПЛОЩАДЬ: | AA54: 67 | AB54: ПЛОЩАДЬ: | AC54: 68 | AD54: ПЛОЩАДЬ: | AE54: 68 | AF54: ПЛОЩАДЬ: | AG54: 68 | AH54: ПЛОЩАДЬ: | AI54: 69 | AL54: ПЛОЩАДЬ: | AM54: 67 | AN54: ПЛОЩАДЬ: | AO54: 68 | AP54: ПЛОЩАДЬ: | AQ54: 68 | AR54: ПЛОЩАДЬ: | AS54: 68 | AT54: ПЛОЩАДЬ: | AU54: 69 | AV54: ПЛОЩАДЬ: | AW54: 69 | AX54: ПЛОЩАДЬ: | AY54: 69 | AZ54: ПЛОЩАДЬ: | BA54: 70
...
